Workbook

Sheet Financial Analysis Memo
A1: Vertical Analysis/Common Sized Income Statement | B1: Divide all the like items by revenue, in come statement. Allows comparison with other companies in the same industry
A2: Horizontal Analysis/Trend Analysis | B2: Move across the income statement, comparing year over year performance
A3: Growth Rates | B3: Looks at historical performance an allows for projection of future performance | D3: Year-over-year; regression analysis; Bottom-up analysis (starting with individual drivers of revenue in the business); Top-down analysis (starting with market size and market share); Other forecasting methods
A4: Profitability Ratios | B4: Income compare to revenue | D4: Gross profit margin; EBITDA margin; EBIT magin; Net Profit margin
A5: Liquidity Ratios | B5: Short term ability to meet obligations | D5: Current ratio; Acid test ratio; Cash ratio; Net working capital
A6: Efficiency Ratios | B6: Balance sheet and ability to generate revenue | D6: Inventory turnover (days in inventor); Accounts receivable turnover (days receivable); Accounts payable turnover (days payable); Asset turnover, Fixed asset turnover, Cash conversion
A7: Leverage Ratios | B7: Shows how much debt is present compared to | D7: Debt to Equity; Debt to EBITDA; EBIT to Interest (Interest Coverage); Dupont analysis (a combination of ratios, often referred to as the pyramid of ratios, including leverage and liquidity analysis)
A8: Cash flow Analysis | B8: Clear picture on how much cash a company is generating | D8: Operating cash flow (OCF); Free cash flow (FCF); Free cash flow to the firm (FCFF); Free cash flow to equity (FCFE)
A9: Rates of Return (ROI) Ratios | B9: Return for an investor | D9: ROE; ROA; ROIC; Dividend yield; Capital gain; Accounting rate of return (ARR); Internal rate of return (IRR)
A10: Valuation Analysis | B10: Cost approach -> Cost to build & Replacement cost; Market approach (relative value) -> Public company comparables & Precedent transactions; DCF -> Forecast future cash flows
A11: Scenario and Sensitivity | B11: Can be layered on top of valuation work. Looks to understand how sensitive the value of a company is relative to changes in operating assumptions. Different scenarios can be used to better understand outcome.
A12: Variance Analysis | B12: Is the process of comparing actual results to budget or forecast

Sheet Vertical Analysis
A1: Cross Sectional Techniques
A2: Vertical Analysis/Common Sized Income Statement
A4: Monster-US
A5: Income Statement ($'000)
B6: FY2025A
A7: Revenue | B7: 8294343
A8: Cost of sales | B8: -3662148
A9: Gross margin | B9: =B8+B7 -> 4632195
A11: Freight-Out Costs | B11: -237000
A12: Advertising and Promotional Expenses | B12: -599900
A13: Other expenses | B13: -1261500
A14: Total Operating Costs | B14: =B13+B12+B11 -> -2098400
A15: EBITDA | B15: =B14+B9 -> 2533795
A17: Depreciation | B17: -114441
A18: EBIT | B18: =B15+B17 -> 2419354
A20: INTEREST AND OTHER INCOME (EXPENSE), NET | B20: 63175
A21: INCOME BEFORE PROVISION FOR INCOME TAXES | B21: =B18+B20 -> 2482529
A23: PROVISION FOR INCOME TAXES | B23: -577097
A24: Tax Rate | B24: 0.23246335
A25: NET INCOME | B25: =B21+B23 -> 1905432
A27: Monster-US
A28: Balance Sheet ($'000) | B28: FY2025A
A29: Current assets
A30: Cash and cash equivalents | B30: 2088117
A31: Short-term investments | B31: 677084
A32: Accounts receivable, net | B32: 1618072
A33: Inventories | B33: 799623
A34: Prepaid expenses and other current assets | B34: 103551
A35: Intangibles held-for-sale | B35: 0
A36: Prepaid Income Taxes | B36: 74637
A37: Deferred income tax | B37: 0
A38: Total current assets | B38: =B37+B34+B33+B32+B31+B30+B36+B35 -> 5361084
A40: Long-term assets
A41: Investments | B41: 48329
A42: Property and equipment, net | B42: 1081544
A43: Deferred Income Taxes | B43: 188646
A44: Intangible assets, net | B44: 1379268
A45: Goodwill | B45: 1331643
A46: Other assets | B46: 159431
A47: Total long-term assets | B47: =B46+B45+B44+B42+B43+B41 -> 4188861
...

Sheet Horizontal Analysis
A1: Cross Sectional Techniques
A2: Horizontal Analysis/Trend Analysis | B2: Move across the income statement, comparing year over year performance (dividing each line item by revenue)
A4: Monster-US
A5: Income Statement ($'000)
B6: 2010 | C6: =B6+1 -> 2011 | D6: =C6+1 -> 2012 | E6: =D6+1 -> 2013 | F6: =E6+1 -> 2014 | G6: =F6+1 -> 2015 | H6: =G6+1 -> 2016 | I6: =H6+1 -> 2017 | J6: =I6+1 -> 2018 | ... N6: =M6+1 -> 2022 | O6: FY2023A | P6: FY2024A | Q6: FY2025A
A7: Net sales | B7: 1303942 | C7: 1703230 | D7: 2060702 | E7: 2246428 | F7: 2464867 | G7: 2722564 | H7: 3049393 | I7: 3369045 | J7: 3807183 | K7: 4200819 | L7: 4598638 | M7: 5541352 | N7: 6311050 | O7: 7140027 | P7: 7492709 | Q7: 8294343
A8: Cost of sales | B8: 623702 | C8: 808921 | D8: 995046 | E8: 1073497 | F8: 1125057 | G8: 1090263 | H8: 1107393 | I8: 1231355 | J8: 1511808 | K8: 1682234 | L8: 1874758 | M8: 2432839 | N8: 3136483 | O8: 3345821 | P8: 3443831 | Q8: 3662148
A9: Gross profit | B9: =B7-B8 -> 680240 | C9: =C7-C8 -> 894309 | D9: =D7-D8 -> 1065656 | E9: =E7-E8 -> 1172931 | F9: =F7-F8 -> 1339810 | G9: =G7-G8 -> 1632301 | H9: =H7-H8 -> 1942000 | I9: =I7-I8 -> 2137690 | ... Q9: =Q7-Q8 -> 4632195
A11: Selling, general and administrative | B11: 0 | C11: 0 | D11: 0 | E11: 0 | F11: 0 | G11: 0 | H11: 0 | I11: 0 | J11: 0 | K11: 0 | L11: 0 | M11: 0 | N11: 0 | O11: 0 | P11: 0 | Q11: 0
A12: Freight-Out-Cots | B12: 47400 | C12: 60500 | D12: 76100 | E12: 84000 | F12: 92700 | G12: 87000 | H12: 83600 | I12: 91900 | J12: 128500 | K12: 122500 | L12: 134100 | M12: 213900 | N12: 249200 | O12: 223600 | P12: 224200 | Q12: 237000
A13: Advertising and Promotional | B13: 104900 | C13: 148800 | D13: 165400 | E13: 181800 | F13: 171500 | G13: 209700 | H13: 270600 | I13: 324000 | J13: 353900 | K13: 391600 | L13: 345700 | M13: 417600 | N13: 460700 | O13: 528900 | P13: 584100 | Q13: 599900
A14: Other Expenses | B14: 180126 | C14: 228586 | D14: 273533 | E14: 334215 | F14: 328105 | G14: 603418 | H14: 502462 | I14: 523003 | J14: 529356 | K14: 601546 | L14: 610927 | M14: 679546 | N14: 879946 | O14: 1088351 | P14: 1310284 | Q14: 1375941
A15: Total Operating expenses | B15: =B14+B13+B12+B11 -> 332426 | C15: =C14+C13+C12+C11 -> 437886 | D15: =D14+D13+D12+D11 -> 515033 | E15: =E14+E13+E12+E11 -> 600015 | F15: =F14+F13+F12+F11 -> 592305 | G15: =G14+G13+G12+G11 -> 900118 | H15: =H14+H13+H12+H11 -> 856662 | I15: =I14+I13+I12+I11 -> 938903 | ... Q15: =Q14+Q13+Q12+Q11 -> 2212841
A16: Operating income (loss) | B16: =B9-B15 -> 347814 | C16: =C9-C15 -> 456423 | D16: =D9-D15 -> 550623 | E16: =E9-E15 -> 572916 | F16: =F9-F15 -> 747505 | G16: =G9-G15 -> 732183 | H16: =H9-H15 -> 1085338 | I16: =I9-I15 -> 1198787 | ... Q16: =Q9-Q15 -> 2419354
A18: Interest income | B18: 0 | C18: 0 | D18: 0 | E18: 0 | F18: 0 | G18: 0 | H18: 0 | I18: 0 | J18: 0 | K18: 0 | L18: 0 | M18: 0 | N18: 0 | O18: 0 | P18: 0 | Q18: 0
A19: Interest expense | B19: 0 | C19: 0 | D19: 0 | E19: 0 | F19: 0 | G19: 0 | H19: 0 | I19: 0 | J19: 0 | K19: 0 | L19: 0 | M19: 0 | N19: 0 | O19: 0 | P19: 0 | Q19: 0
A20: Other income (expense), net | B20: 0 | C20: 0 | D20: 0 | E20: 0 | F20: 0 | G20: -2105 | H20: -5653 | I20: 2836 | J20: 9653 | K20: 13023 | L20: -6996 | M20: 3952 | N20: -12757 | O20: 115127 | P20: 59165 | Q20: 63175
A21: Income before income taxes | B21: =B16-B19+B18-B20 -> 347814 | C21: =C16-C19+C18-C20 -> 456423 | D21: =D16-D19+D18-D20 -> 550623 | E21: =E16-E19+E18-E20 -> 572916 | F21: =F16-F19+F18-F20 -> 747505 | G21: =G16-G19+G18-G20 -> 734288 | H21: =H16-H19+H18-H20 -> 1090991 | I21: =I16-I19+I18-I20 -> 1195951 | ... Q21: =Q16-Q19+Q18-Q20 -> 2356179
A23: Provision for income taxes | B23: 137273 | C23: 171051 | D23: 209134 | E23: 225233 | F23: 262603 | G23: 344815 | H23: 367000 | I23: 380945 | J23: 300268 | K23: 308127 | L23: 216563 | M23: 423944 | N23: 380340 | O23: 437494 | P23: 480411 | Q23: 577097
A24: Net income (loss) | B24: =B21-B23 -> 210541 | C24: =C21-C23 -> 285372 | D24: =D21-D23 -> 341489 | E24: =E21-E23 -> 347683 | F24: =F21-F23 -> 484902 | G24: =G21-G23 -> 389473 | H24: =H21-H23 -> 723991 | I24: =I21-I23 -> 815006 | ... Q24: =Q21-Q23 -> 1779082
A26: Monster-US
A27: Balance Sheet ($'000)
B28: 2010 | C28: =B28+1 -> 2011 | D28: =C28+1 -> 2012 | E28: =D28+1 -> 2013 | F28: =E28+1 -> 2014 | G28: =F28+1 -> 2015 | H28: =G28+1 -> 2016 | I28: =H28+1 -> 2017 | J28: =I28+1 -> 2018 | ... N28: =M28+1 -> 2022 | O28: 2023 | P28: =O28+1 -> 2024 | Q28: =P28+1 -> 2025
A29: Current assets
A30: Cash and cash equivalents | B30: 354842 | C30: 359331 | D30: 222514 | E30: 211349 | F30: 370323 | G30: 2175417 | H30: 377582 | I30: 528622 | J30: 637513 | K30: 797957 | L30: 1180413 | M30: 1326462 | N30: 1307141 | O30: 2297675 | P30: 1533287 | Q30: 2088117
A31: Short-term investments | B31: 244649 | C31: 411282 | D31: 97042 | E31: 402247 | F31: 781134 | G31: 744610 | H31: 220554 | I31: 672933 | J31: 320650 | K31: 533063 | L31: 881354 | M31: 1749727 | N31: 1362314 | O31: 955605 | P31: 0 | Q31: 677084
A32: Accounts receivable, net | B32: 101635 | C32: 218741 | D32: 236710 | E32: =291638+4542 -> 296180 | F32: =280203+552 -> 280755 | G32: =352955+125000 -> 477955 | H32: =448051+125000 -> 573051 | I32: 449476 | J32: 484562 | K32: 540330 | L32: 666012 | M32: 896658 | N32: 1016203 | O32: 1193964 | P32: 1221646 | Q32: 1618072
A33: Inventories | B33: 153241 | C33: 155613 | D33: 203106 | E33: 221449 | F33: 174573 | G33: 156121 | H33: 161971 | I33: 255745 | J33: 277705 | K33: 360731 | L33: 333085 | M33: 593357 | N33: 935631 | O33: 971406 | P33: 737107 | Q33: 799623
A34: Prepaid expenses and other current assets | B34: 17022 | C34: 20912 | D34: 24983 | E34: 21376 | F34: 19673 | G34: 26967 | H34: 32562 | I34: 40877 | J34: 44909 | K34: 54868 | L34: 55358 | M34: 82668 | N34: 109823 | O34: 116195 | P34: 107262 | Q34: 103551
A35: Intangibles held-for-sale | E35: 0 | F35: 18079 | G35: 0 | H35: 0
A36: Prepaid Income Taxes | B36: 9992 | C36: 370 | D36: 33709 | E36: 9518 | F36: 8617 | G36: 18462 | H36: 66550 | I36: 138724 | J36: 38831 | L36: 24733 | M36: 33238 | N36: 33785 | O36: 54151 | P36: 42202 | Q36: 74637
A37: Deferred income tax | B37: 16772 | C37: 16428 | D37: 17004 | E37: 20924 | F37: 40275 | G37: 0 | H37: 0
A38: Total current assets | B38: =B37+B34+B33+B32+B31+B30+B36+B35 -> 898153 | C38: =C37+C34+C33+C32+C31+C30+C36+C35 -> 1182677 | D38: =D37+D34+D33+D32+D31+D30+D36+D35 -> 835068 | E38: =E37+E34+E33+E32+E31+E30+E36+E35 -> 1183043 | F38: =F37+F34+F33+F32+F31+F30+F36+F35 -> 1693429 | G38: =G37+G34+G33+G32+G31+G30+G36+G35 -> 3599532 | H38: =H37+H34+H33+H32+H31+H30+H36+H35 -> 1432270 | I38: =I37+I34+I33+I32+I31+I30+I36+I35 -> 2086377 | ... Q38: =Q37+Q34+Q33+Q32+Q31+Q30+Q36+Q35 -> 5361084
A40: Long-term assets
A41: Investments | B41: 44189 | C41: 23194 | D41: 21393 | E41: 9792 | F41: 42940 | G41: 15348 | H41: 2394 | I41: 2366 | L41: 44291 | M41: 99419 | N41: 61443 | O41: 76431 | P41: 0 | Q41: 48329
A42: Property and equipment, net | B42: 34551 | C42: 45151 | D42: 69137 | E42: 88143 | F42: 90156 | G42: 97354 | H42: 173343 | I42: 230276 | J42: 243051 | K42: 298640 | L42: 314656 | M42: 313753 | N42: 516897 | O42: 890796 | P42: 1047024 | Q42: 1081544
A43: Deferred Income Taxes | B43: 58475 | C43: 58576 | D43: 59503 | E43: 63611 | F43: 54106 | G43: 140468 | H43: 159556 | I43: 92333 | J43: 85687 | L43: 241650 | M43: 225221 | N43: 177039 | O43: 175003 | P43: 184260 | Q43: 188646
A44: Intangible assets, net | B44: 43316 | C44: 48396 | D44: 54648 | E44: 65774 | F44: 50748 | G44: 427986 | H44: 1032635 | I44: 1034085 | J44: 1045878 | K44: 1052105 | L44: 1059046 | M44: 1072386 | N44: 1220410 | O44: 1427139 | P44: 1414252 | Q44: 1379268
A45: Goodwill | B45: 0 | C45: 0 | D45: 0 | E45: 0 | F45: 0 | G45: 1279715 | H45: 1331643 | I45: 1331643 | J45: 1331643 | K45: 1331643 | L45: 1331643 | M45: 1331643 | N45: 1417941 | O45: 1417941 | P45: 1331643 | Q45: 1331643
A46: Other assets | B46: 3447 | C46: 4405 | D46: 3576 | E46: 10146 | F46: 7496 | G46: 10874 | H46: 21630 | I46: 13932 | J46: 16462 | K46: 53973 | L46: 70475 | M46: 80252 | N46: 134478 | O46: 110216 | P46: 100406 | Q46: 159431
...

Sheet Common Size
A1: Common sized
A3: Monster-US
A4: Income Statement ($'000)
B5: 2010 | C5: =B5+1 -> 2011 | D5: =C5+1 -> 2012 | E5: =D5+1 -> 2013 | F5: =E5+1 -> 2014 | G5: =F5+1 -> 2015 | H5: =G5+1 -> 2016 | I5: =H5+1 -> 2017 | J5: =I5+1 -> 2018 | ... N5: =M5+1 -> 2022 | O5: FY2023A | P5: FY2024A | Q5: FY2025A
A6: Net sales | B6: 1303942 | C6: 1703230 | D6: 2060702 | E6: 2246428 | F6: 2464867 | G6: 2722564 | H6: 3049393 | I6: 3369045 | J6: 3807183 | K6: 4200819 | L6: 4598638 | M6: 5541352 | N6: 6311050 | O6: 7140027 | P6: 7492709 | Q6: 8294343
A7: Cost of sales | B7: 623702 | C7: 808921 | D7: 995046 | E7: 1073497 | F7: 1125057 | G7: 1090263 | H7: 1107393 | I7: 1231355 | J7: 1511808 | K7: 1682234 | L7: 1874758 | M7: 2432839 | N7: 3136483 | O7: 3345821 | P7: 3443831 | Q7: 3662148
A8: Gross profit | B8: =B6-B7 -> 680240 | C8: =C6-C7 -> 894309 | D8: =D6-D7 -> 1065656 | E8: =E6-E7 -> 1172931 | F8: =F6-F7 -> 1339810 | G8: =G6-G7 -> 1632301 | H8: =H6-H7 -> 1942000 | I8: =I6-I7 -> 2137690 | ... Q8: =Q6-Q7 -> 4632195
A10: Selling, general and administrative | B10: 0 | C10: 0 | D10: 0 | E10: 0 | F10: 0 | G10: 0 | H10: 0 | I10: 0 | J10: 0 | K10: 0 | L10: 0 | M10: 0 | N10: 0 | O10: 0 | P10: 0 | Q10: 0
A11: Freight-Out-Cots | B11: 47400 | C11: 60500 | D11: 76100 | E11: 84000 | F11: 92700 | G11: 87000 | H11: 83600 | I11: 91900 | J11: 128500 | K11: 122500 | L11: 134100 | M11: 213900 | N11: 249200 | O11: 223600 | P11: 224200 | Q11: 237000
A12: Advertising and Promotional | B12: 104900 | C12: 148800 | D12: 165400 | E12: 181800 | F12: 171500 | G12: 209700 | H12: 270600 | I12: 324000 | J12: 353900 | K12: 391600 | L12: 345700 | M12: 417600 | N12: 460700 | O12: 528900 | P12: 584100 | Q12: 599900
A13: Other Expenses | B13: 180126 | C13: 228586 | D13: 273533 | E13: 334215 | F13: 328105 | G13: 603418 | H13: 502462 | I13: 523003 | J13: 529356 | K13: 601546 | L13: 610927 | M13: 679546 | N13: 879946 | O13: 1088351 | P13: 1310284 | Q13: 1375941
A14: Total Operating expenses | B14: =B13+B12+B11+B10 -> 332426 | C14: =C13+C12+C11+C10 -> 437886 | D14: =D13+D12+D11+D10 -> 515033 | E14: =E13+E12+E11+E10 -> 600015 | F14: =F13+F12+F11+F10 -> 592305 | G14: =G13+G12+G11+G10 -> 900118 | H14: =H13+H12+H11+H10 -> 856662 | I14: =I13+I12+I11+I10 -> 938903 | ... Q14: =Q13+Q12+Q11+Q10 -> 2212841
A15: Operating income (loss) | B15: =B8-B14 -> 347814 | C15: =C8-C14 -> 456423 | D15: =D8-D14 -> 550623 | E15: =E8-E14 -> 572916 | F15: =F8-F14 -> 747505 | G15: =G8-G14 -> 732183 | H15: =H8-H14 -> 1085338 | I15: =I8-I14 -> 1198787 | ... Q15: =Q8-Q14 -> 2419354
A17: Interest income | B17: 0 | C17: 0 | D17: 0 | E17: 0 | F17: 0 | G17: 0 | H17: 0 | I17: 0 | J17: 0 | K17: 0 | L17: 0 | M17: 0 | N17: 0 | O17: 0 | P17: 0 | Q17: 0
A18: Interest expense | B18: 0 | C18: 0 | D18: 0 | E18: 0 | F18: 0 | G18: 0 | H18: 0 | I18: 0 | J18: 0 | K18: 0 | L18: 0 | M18: 0 | N18: 0 | O18: 0 | P18: 0 | Q18: 0
A19: Other income (expense), net | B19: 0 | C19: 0 | D19: 0 | E19: 0 | F19: 0 | G19: -2105 | H19: -5653 | I19: 2836 | J19: 9653 | K19: 13023 | L19: -6996 | M19: 3952 | N19: -12757 | O19: 115127 | P19: 59165 | Q19: 63175
A20: Income before income taxes | B20: =B15-B18+B17-B19 -> 347814 | C20: =C15-C18+C17-C19 -> 456423 | D20: =D15-D18+D17-D19 -> 550623 | E20: =E15-E18+E17-E19 -> 572916 | F20: =F15-F18+F17-F19 -> 747505 | G20: =G15-G18+G17-G19 -> 734288 | H20: =H15-H18+H17-H19 -> 1090991 | I20: =I15-I18+I17-I19 -> 1195951 | ... Q20: =Q15-Q18+Q17-Q19 -> 2356179
A22: Provision for income taxes | B22: 137273 | C22: 171051 | D22: 209134 | E22: 225233 | F22: 262603 | G22: 344815 | H22: 367000 | I22: 380945 | J22: 300268 | K22: 308127 | L22: 216563 | M22: 423944 | N22: 380340 | O22: 437494 | P22: 480411 | Q22: 577097
A23: Net income (loss) | B23: =B20-B22 -> 210541 | C23: =C20-C22 -> 285372 | D23: =D20-D22 -> 341489 | E23: =E20-E22 -> 347683 | F23: =F20-F22 -> 484902 | G23: =G20-G22 -> 389473 | H23: =H20-H22 -> 723991 | I23: =I20-I22 -> 815006 | ... Q23: =Q20-Q22 -> 1779082
A27: Monster-US
A28: Balance Sheet ($'000)
B29: 2010 | C29: =B29+1 -> 2011 | D29: =C29+1 -> 2012 | E29: =D29+1 -> 2013 | F29: =E29+1 -> 2014 | G29: =F29+1 -> 2015 | H29: =G29+1 -> 2016 | I29: =H29+1 -> 2017 | J29: =I29+1 -> 2018 | ... N29: =M29+1 -> 2022 | O29: 2023 | P29: =O29+1 -> 2024 | Q29: =P29+1 -> 2025
A30: Current assets
A31: Cash and cash equivalents | B31: 354842 | C31: 359331 | D31: 222514 | E31: 211349 | F31: 370323 | G31: 2175417 | H31: 377582 | I31: 528622 | J31: 637513 | K31: 797957 | L31: 1180413 | M31: 1326462 | N31: 1307141 | O31: 2297675 | P31: 1533287 | Q31: 2088117
A32: Short-term investments | B32: 244649 | C32: 411282 | D32: 97042 | E32: 402247 | F32: 781134 | G32: 744610 | H32: 220554 | I32: 672933 | J32: 320650 | K32: 533063 | L32: 881354 | M32: 1749727 | N32: 1362314 | O32: 955605 | P32: 0 | Q32: 677084
A33: Accounts receivable, net | B33: 101635 | C33: 218741 | D33: 236710 | E33: =291638+4542 -> 296180 | F33: =280203+552 -> 280755 | G33: =352955+125000 -> 477955 | H33: =448051+125000 -> 573051 | I33: 449476 | J33: 484562 | K33: 540330 | L33: 666012 | M33: 896658 | N33: 1016203 | O33: 1193964 | P33: 1221646 | Q33: 1618072
A34: Inventories | B34: 153241 | C34: 155613 | D34: 203106 | E34: 221449 | F34: 174573 | G34: 156121 | H34: 161971 | I34: 255745 | J34: 277705 | K34: 360731 | L34: 333085 | M34: 593357 | N34: 935631 | O34: 971406 | P34: 737107 | Q34: 799623
A35: Prepaid expenses and other current assets | B35: 17022 | C35: 20912 | D35: 24983 | E35: 21376 | F35: 19673 | G35: 26967 | H35: 32562 | I35: 40877 | J35: 44909 | K35: 54868 | L35: 55358 | M35: 82668 | N35: 109823 | O35: 116195 | P35: 107262 | Q35: 103551
A36: Intangibles held-for-sale | E36: 0 | F36: 18079 | G36: 0 | H36: 0
A37: Prepaid Income Taxes | B37: 9992 | C37: 370 | D37: 33709 | E37: 9518 | F37: 8617 | G37: 18462 | H37: 66550 | I37: 138724 | J37: 38831 | L37: 24733 | M37: 33238 | N37: 33785 | O37: 54151 | P37: 42202 | Q37: 74637
A38: Deferred income tax | B38: 16772 | C38: 16428 | D38: 17004 | E38: 20924 | F38: 40275 | G38: 0 | H38: 0
A39: Total current assets | B39: =B38+B35+B34+B33+B32+B31+B37+B36 -> 898153 | C39: =C38+C35+C34+C33+C32+C31+C37+C36 -> 1182677 | D39: =D38+D35+D34+D33+D32+D31+D37+D36 -> 835068 | E39: =E38+E35+E34+E33+E32+E31+E37+E36 -> 1183043 | F39: =F38+F35+F34+F33+F32+F31+F37+F36 -> 1693429 | G39: =G38+G35+G34+G33+G32+G31+G37+G36 -> 3599532 | H39: =H38+H35+H34+H33+H32+H31+H37+H36 -> 1432270 | I39: =I38+I35+I34+I33+I32+I31+I37+I36 -> 2086377 | ... Q39: =Q38+Q35+Q34+Q33+Q32+Q31+Q37+Q36 -> 5361084
A41: Long-term assets
A42: Investments | B42: 44189 | C42: 23194 | D42: 21393 | E42: 9792 | F42: 42940 | G42: 15348 | H42: 2394 | I42: 2366 | L42: 44291 | M42: 99419 | N42: 61443 | O42: 76431 | P42: 0 | Q42: 48329
A43: Property and equipment, net | B43: 34551 | C43: 45151 | D43: 69137 | E43: 88143 | F43: 90156 | G43: 97354 | H43: 173343 | I43: 230276 | J43: 243051 | K43: 298640 | L43: 314656 | M43: 313753 | N43: 516897 | O43: 890796 | P43: 1047024 | Q43: 1081544
A44: Deferred Income Taxes | B44: 58475 | C44: 58576 | D44: 59503 | E44: 63611 | F44: 54106 | G44: 140468 | H44: 159556 | I44: 92333 | J44: 85687 | L44: 241650 | M44: 225221 | N44: 177039 | O44: 175003 | P44: 184260 | Q44: 188646
A45: Intangible assets, net | B45: 43316 | C45: 48396 | D45: 54648 | E45: 65774 | F45: 50748 | G45: 427986 | H45: 1032635 | I45: 1034085 | J45: 1045878 | K45: 1052105 | L45: 1059046 | M45: 1072386 | N45: 1220410 | O45: 1427139 | P45: 1414252 | Q45: 1379268
A46: Goodwill | B46: 0 | C46: 0 | D46: 0 | E46: 0 | F46: 0 | G46: 1279715 | H46: 1331643 | I46: 1331643 | J46: 1331643 | K46: 1331643 | L46: 1331643 | M46: 1331643 | N46: 1417941 | O46: 1417941 | P46: 1331643 | Q46: 1331643
A47: Other assets | B47: 3447 | C47: 4405 | D47: 3576 | E47: 10146 | F47: 7496 | G47: 10874 | H47: 21630 | I47: 13932 | J47: 16462 | K47: 53973 | L47: 70475 | M47: 80252 | N47: 134478 | O47: 110216 | P47: 100406 | Q47: 159431
A48: Total long-term assets | B48: =B47+B46+B45+B43+B44+B42 -> 183978 | C48: =C47+C46+C45+C43+C44+C42 -> 179722 | D48: =D47+D46+D45+D43+D44+D42 -> 208257 | E48: =E47+E46+E45+E43+E44+E42 -> 237466 | F48: =F47+F46+F45+F43+F44+F42 -> 245446 | G48: =G47+G46+G45+G43+G44+G42 -> 1971745 | H48: =H47+H46+H45+H43+H44+H42 -> 2721201 | I48: =I47+I46+I45+I43+I44+I42 -> 2704635 | ... Q48: =Q47+Q46+Q45+Q43+Q44+Q42 -> 4188861
...

Sheet Index Analysis
A1: Index Analysis
A3: Monster-US
A4: Income Statement ($'000)
B5: 2010 | C5: =B5+1 -> 2011 | D5: =C5+1 -> 2012 | E5: =D5+1 -> 2013 | F5: =E5+1 -> 2014 | G5: =F5+1 -> 2015 | H5: =G5+1 -> 2016 | I5: =H5+1 -> 2017 | J5: =I5+1 -> 2018 | ... N5: =M5+1 -> 2022 | O5: FY2023A | P5: FY2024A | Q5: FY2025A
A6: Net sales | B6: 1303942 | C6: 1703230 | D6: 2060702 | E6: 2246428 | F6: 2464867 | G6: 2722564 | H6: 3049393 | I6: 3369045 | J6: 3807183 | K6: 4200819 | L6: 4598638 | M6: 5541352 | N6: 6311050 | O6: 7140027 | P6: 7492709 | Q6: 8294343
A7: Cost of sales | B7: 623702 | C7: 808921 | D7: 995046 | E7: 1073497 | F7: 1125057 | G7: 1090263 | H7: 1107393 | I7: 1231355 | J7: 1511808 | K7: 1682234 | L7: 1874758 | M7: 2432839 | N7: 3136483 | O7: 3345821 | P7: 3443831 | Q7: 3662148
A8: Gross profit | B8: =B6-B7 -> 680240 | C8: =C6-C7 -> 894309 | D8: =D6-D7 -> 1065656 | E8: =E6-E7 -> 1172931 | F8: =F6-F7 -> 1339810 | G8: =G6-G7 -> 1632301 | H8: =H6-H7 -> 1942000 | I8: =I6-I7 -> 2137690 | ... Q8: =Q6-Q7 -> 4632195
A10: Selling, general and administrative | B10: 0 | C10: 0 | D10: 0 | E10: 0 | F10: 0 | G10: 0 | H10: 0 | I10: 0 | J10: 0 | K10: 0 | L10: 0 | M10: 0 | N10: 0 | O10: 0 | P10: 0 | Q10: 0
A11: Freight-Out-Cots | B11: 47400 | C11: 60500 | D11: 76100 | E11: 84000 | F11: 92700 | G11: 87000 | H11: 83600 | I11: 91900 | J11: 128500 | K11: 122500 | L11: 134100 | M11: 213900 | N11: 249200 | O11: 223600 | P11: 224200 | Q11: 237000
A12: Advertising and Promotional | B12: 104900 | C12: 148800 | D12: 165400 | E12: 181800 | F12: 171500 | G12: 209700 | H12: 270600 | I12: 324000 | J12: 353900 | K12: 391600 | L12: 345700 | M12: 417600 | N12: 460700 | O12: 528900 | P12: 584100 | Q12: 599900
A13: Other Expenses | B13: 180126 | C13: 228586 | D13: 273533 | E13: 334215 | F13: 328105 | G13: 603418 | H13: 502462 | I13: 523003 | J13: 529356 | K13: 601546 | L13: 610927 | M13: 679546 | N13: 879946 | O13: 1088351 | P13: 1310284 | Q13: 1375941
A14: Total Operating expenses | B14: =B13+B12+B11+B10 -> 332426 | C14: =C13+C12+C11+C10 -> 437886 | D14: =D13+D12+D11+D10 -> 515033 | E14: =E13+E12+E11+E10 -> 600015 | F14: =F13+F12+F11+F10 -> 592305 | G14: =G13+G12+G11+G10 -> 900118 | H14: =H13+H12+H11+H10 -> 856662 | I14: =I13+I12+I11+I10 -> 938903 | ... Q14: =Q13+Q12+Q11+Q10 -> 2212841
A15: Operating income (loss) | B15: =B8-B14 -> 347814 | C15: =C8-C14 -> 456423 | D15: =D8-D14 -> 550623 | E15: =E8-E14 -> 572916 | F15: =F8-F14 -> 747505 | G15: =G8-G14 -> 732183 | H15: =H8-H14 -> 1085338 | I15: =I8-I14 -> 1198787 | ... Q15: =Q8-Q14 -> 2419354
A17: Interest income | B17: 0 | C17: 0 | D17: 0 | E17: 0 | F17: 0 | G17: 0 | H17: 0 | I17: 0 | J17: 0 | K17: 0 | L17: 0 | M17: 0 | N17: 0 | O17: 0 | P17: 0 | Q17: 0
A18: Interest expense | B18: 0 | C18: 0 | D18: 0 | E18: 0 | F18: 0 | G18: 0 | H18: 0 | I18: 0 | J18: 0 | K18: 0 | L18: 0 | M18: 0 | N18: 0 | O18: 0 | P18: 0 | Q18: 0
A19: Other income (expense), net | B19: 0 | C19: 0 | D19: 0 | E19: 0 | F19: 0 | G19: -2105 | H19: -5653 | I19: 2836 | J19: 9653 | K19: 13023 | L19: -6996 | M19: 3952 | N19: -12757 | O19: 115127 | P19: 59165 | Q19: 63175
A20: Income before income taxes | B20: =B15-B18+B17-B19 -> 347814 | C20: =C15-C18+C17-C19 -> 456423 | D20: =D15-D18+D17-D19 -> 550623 | E20: =E15-E18+E17-E19 -> 572916 | F20: =F15-F18+F17-F19 -> 747505 | G20: =G15-G18+G17-G19 -> 734288 | H20: =H15-H18+H17-H19 -> 1090991 | I20: =I15-I18+I17-I19 -> 1195951 | ... Q20: =Q15-Q18+Q17-Q19 -> 2356179
A22: Provision for income taxes | B22: 137273 | C22: 171051 | D22: 209134 | E22: 225233 | F22: 262603 | G22: 344815 | H22: 367000 | I22: 380945 | J22: 300268 | K22: 308127 | L22: 216563 | M22: 423944 | N22: 380340 | O22: 437494 | P22: 480411 | Q22: 577097
A23: Net income (loss) | B23: =B20-B22 -> 210541 | C23: =C20-C22 -> 285372 | D23: =D20-D22 -> 341489 | E23: =E20-E22 -> 347683 | F23: =F20-F22 -> 484902 | G23: =G20-G22 -> 389473 | H23: =H20-H22 -> 723991 | I23: =I20-I22 -> 815006 | ... Q23: =Q20-Q22 -> 1779082
A27: Monster-US
A28: Balance Sheet ($'000)
B29: 2010 | C29: =B29+1 -> 2011 | D29: =C29+1 -> 2012 | E29: =D29+1 -> 2013 | F29: =E29+1 -> 2014 | G29: =F29+1 -> 2015 | H29: =G29+1 -> 2016 | I29: =H29+1 -> 2017 | J29: =I29+1 -> 2018 | ... N29: =M29+1 -> 2022 | O29: 2023 | P29: =O29+1 -> 2024 | Q29: =P29+1 -> 2025
A30: Current assets
A31: Cash and cash equivalents | B31: 354842 | C31: 359331 | D31: 222514 | E31: 211349 | F31: 370323 | G31: 2175417 | H31: 377582 | I31: 528622 | J31: 637513 | K31: 797957 | L31: 1180413 | M31: 1326462 | N31: 1307141 | O31: 2297675 | P31: 1533287 | Q31: 2088117
A32: Short-term investments | B32: 244649 | C32: 411282 | D32: 97042 | E32: 402247 | F32: 781134 | G32: 744610 | H32: 220554 | I32: 672933 | J32: 320650 | K32: 533063 | L32: 881354 | M32: 1749727 | N32: 1362314 | O32: 955605 | P32: 0 | Q32: 677084
A33: Accounts receivable, net | B33: 101635 | C33: 218741 | D33: 236710 | E33: =291638+4542 -> 296180 | F33: =280203+552 -> 280755 | G33: =352955+125000 -> 477955 | H33: =448051+125000 -> 573051 | I33: 449476 | J33: 484562 | K33: 540330 | L33: 666012 | M33: 896658 | N33: 1016203 | O33: 1193964 | P33: 1221646 | Q33: 1618072
A34: Inventories | B34: 153241 | C34: 155613 | D34: 203106 | E34: 221449 | F34: 174573 | G34: 156121 | H34: 161971 | I34: 255745 | J34: 277705 | K34: 360731 | L34: 333085 | M34: 593357 | N34: 935631 | O34: 971406 | P34: 737107 | Q34: 799623
A35: Prepaid expenses and other current assets | B35: 17022 | C35: 20912 | D35: 24983 | E35: 21376 | F35: 19673 | G35: 26967 | H35: 32562 | I35: 40877 | J35: 44909 | K35: 54868 | L35: 55358 | M35: 82668 | N35: 109823 | O35: 116195 | P35: 107262 | Q35: 103551
A36: Intangibles held-for-sale | E36: 0 | F36: 18079 | G36: 0 | H36: 0
A37: Prepaid Income Taxes | B37: 9992 | C37: 370 | D37: 33709 | E37: 9518 | F37: 8617 | G37: 18462 | H37: 66550 | I37: 138724 | J37: 38831 | L37: 24733 | M37: 33238 | N37: 33785 | O37: 54151 | P37: 42202 | Q37: 74637
A38: Deferred income tax | B38: 16772 | C38: 16428 | D38: 17004 | E38: 20924 | F38: 40275 | G38: 0 | H38: 0
A39: Total current assets | B39: =B38+B35+B34+B33+B32+B31+B37+B36 -> 898153 | C39: =C38+C35+C34+C33+C32+C31+C37+C36 -> 1182677 | D39: =D38+D35+D34+D33+D32+D31+D37+D36 -> 835068 | E39: =E38+E35+E34+E33+E32+E31+E37+E36 -> 1183043 | F39: =F38+F35+F34+F33+F32+F31+F37+F36 -> 1693429 | G39: =G38+G35+G34+G33+G32+G31+G37+G36 -> 3599532 | H39: =H38+H35+H34+H33+H32+H31+H37+H36 -> 1432270 | I39: =I38+I35+I34+I33+I32+I31+I37+I36 -> 2086377 | ... Q39: =Q38+Q35+Q34+Q33+Q32+Q31+Q37+Q36 -> 5361084
A41: Long-term assets
A42: Investments | B42: 44189 | C42: 23194 | D42: 21393 | E42: 9792 | F42: 42940 | G42: 15348 | H42: 2394 | I42: 2366 | L42: 44291 | M42: 99419 | N42: 61443 | O42: 76431 | P42: 0 | Q42: 48329
A43: Property and equipment, net | B43: 34551 | C43: 45151 | D43: 69137 | E43: 88143 | F43: 90156 | G43: 97354 | H43: 173343 | I43: 230276 | J43: 243051 | K43: 298640 | L43: 314656 | M43: 313753 | N43: 516897 | O43: 890796 | P43: 1047024 | Q43: 1081544
A44: Deferred Income Taxes | B44: 58475 | C44: 58576 | D44: 59503 | E44: 63611 | F44: 54106 | G44: 140468 | H44: 159556 | I44: 92333 | J44: 85687 | L44: 241650 | M44: 225221 | N44: 177039 | O44: 175003 | P44: 184260 | Q44: 188646
A45: Intangible assets, net | B45: 43316 | C45: 48396 | D45: 54648 | E45: 65774 | F45: 50748 | G45: 427986 | H45: 1032635 | I45: 1034085 | J45: 1045878 | K45: 1052105 | L45: 1059046 | M45: 1072386 | N45: 1220410 | O45: 1427139 | P45: 1414252 | Q45: 1379268
A46: Goodwill | B46: 0 | C46: 0 | D46: 0 | E46: 0 | F46: 0 | G46: 1279715 | H46: 1331643 | I46: 1331643 | J46: 1331643 | K46: 1331643 | L46: 1331643 | M46: 1331643 | N46: 1417941 | O46: 1417941 | P46: 1331643 | Q46: 1331643
A47: Other assets | B47: 3447 | C47: 4405 | D47: 3576 | E47: 10146 | F47: 7496 | G47: 10874 | H47: 21630 | I47: 13932 | J47: 16462 | K47: 53973 | L47: 70475 | M47: 80252 | N47: 134478 | O47: 110216 | P47: 100406 | Q47: 159431
A48: Total long-term assets | B48: =B47+B46+B45+B43+B44+B42 -> 183978 | C48: =C47+C46+C45+C43+C44+C42 -> 179722 | D48: =D47+D46+D45+D43+D44+D42 -> 208257 | E48: =E47+E46+E45+E43+E44+E42 -> 237466 | F48: =F47+F46+F45+F43+F44+F42 -> 245446 | G48: =G47+G46+G45+G43+G44+G42 -> 1971745 | H48: =H47+H46+H45+H43+H44+H42 -> 2721201 | I48: =I47+I46+I45+I43+I44+I42 -> 2704635 | ... Q48: =Q47+Q46+Q45+Q43+Q44+Q42 -> 4188861
...

Sheet Financial Ratios
A1: Profitability Ratios | O1: Income compared to revenue & cogs
A2: Liquidity Ratios | O2: Short term ability to meet obligations
A3: Efficiency Ratios | O3: Balance sheet and ability to generate revenue
A4: Leverage Ratios | O4: Shows how much debt is present compared to
A7: Monster-US
A8: Income Statement ($'000)
B9: 2010 | C9: =B9+1 -> 2011 | D9: =C9+1 -> 2012 | E9: =D9+1 -> 2013 | F9: =E9+1 -> 2014 | G9: =F9+1 -> 2015 | H9: =G9+1 -> 2016 | I9: =H9+1 -> 2017 | J9: =I9+1 -> 2018 | ... N9: =M9+1 -> 2022 | O9: FY2023A | P9: FY2024A | Q9: FY2025A
A10: Net sales | B10: 1303942 | C10: 1703230 | D10: 2060702 | E10: 2246428 | F10: 2464867 | G10: 2722564 | H10: 3049393 | I10: 3369045 | J10: 3807183 | K10: 4200819 | L10: 4598638 | M10: 5541352 | N10: 6311050 | O10: 7140027 | P10: 7492709 | Q10: 8294343
A11: Cost of sales | B11: 623702 | C11: 808921 | D11: 995046 | E11: 1073497 | F11: 1125057 | G11: 1090263 | H11: 1107393 | I11: 1231355 | J11: 1511808 | K11: 1682234 | L11: 1874758 | M11: 2432839 | N11: 3136483 | O11: 3345821 | P11: 3443831 | Q11: 3662148
A12: Gross profit | B12: =B10-B11 -> 680240 | C12: =C10-C11 -> 894309 | D12: =D10-D11 -> 1065656 | E12: =E10-E11 -> 1172931 | F12: =F10-F11 -> 1339810 | G12: =G10-G11 -> 1632301 | H12: =H10-H11 -> 1942000 | I12: =I10-I11 -> 2137690 | ... Q12: =Q10-Q11 -> 4632195
A14: Selling, general and administrative | B14: 0 | C14: 0 | D14: 0 | E14: 0 | F14: 0 | G14: 0 | H14: 0 | I14: 0 | J14: 0 | K14: 0 | L14: 0 | M14: 0 | N14: 0 | O14: 0 | P14: 0 | Q14: 0
A15: Freight-Out-Cots | B15: 47400 | C15: 60500 | D15: 76100 | E15: 84000 | F15: 92700 | G15: 87000 | H15: 83600 | I15: 91900 | J15: 128500 | K15: 122500 | L15: 134100 | M15: 213900 | N15: 249200 | O15: 223600 | P15: 224200 | Q15: 237000
A16: Advertising and Promotional | B16: 104900 | C16: 148800 | D16: 165400 | E16: 181800 | F16: 171500 | G16: 209700 | H16: 270600 | I16: 324000 | J16: 353900 | K16: 391600 | L16: 345700 | M16: 417600 | N16: 460700 | O16: 528900 | P16: 584100 | Q16: 599900
A17: Other Expenses | B17: 180126 | C17: 228586 | D17: 273533 | E17: 334215 | F17: 328105 | G17: 603418 | H17: 502462 | I17: 523003 | J17: 529356 | K17: 601546 | L17: 610927 | M17: 679546 | N17: 879946 | O17: 1088351 | P17: 1310284 | Q17: 1375941
A18: Total Operating expenses | B18: =B17+B16+B15+B14 -> 332426 | C18: =C17+C16+C15+C14 -> 437886 | D18: =D17+D16+D15+D14 -> 515033 | E18: =E17+E16+E15+E14 -> 600015 | F18: =F17+F16+F15+F14 -> 592305 | G18: =G17+G16+G15+G14 -> 900118 | H18: =H17+H16+H15+H14 -> 856662 | I18: =I17+I16+I15+I14 -> 938903 | ... Q18: =Q17+Q16+Q15+Q14 -> 2212841
A19: Operating income (loss) | B19: =B12-B18 -> 347814 | C19: =C12-C18 -> 456423 | D19: =D12-D18 -> 550623 | E19: =E12-E18 -> 572916 | F19: =F12-F18 -> 747505 | G19: =G12-G18 -> 732183 | H19: =H12-H18 -> 1085338 | I19: =I12-I18 -> 1198787 | ... Q19: =Q12-Q18 -> 2419354
A21: Interest income | B21: 0 | C21: 0 | D21: 0 | E21: 0 | F21: 0 | G21: 0 | H21: 0 | I21: 0 | J21: 0 | K21: 0 | L21: 0 | M21: 0 | N21: 0 | O21: 0 | P21: 0 | Q21: 0
A22: Interest expense | B22: 0 | C22: 0 | D22: 0 | E22: 0 | F22: 0 | G22: 0 | H22: 0 | I22: 0 | J22: 0 | K22: 0 | L22: 0 | M22: 0 | N22: 0 | O22: 0 | P22: 0 | Q22: 0
A23: Other income (expense), net | B23: 0 | C23: 0 | D23: 0 | E23: 0 | F23: 0 | G23: -2105 | H23: -5653 | I23: 2836 | J23: 9653 | K23: 13023 | L23: -6996 | M23: 3952 | N23: -12757 | O23: 115127 | P23: 59165 | Q23: 63175
A24: Income before income taxes | B24: =B19-B22+B21-B23 -> 347814 | C24: =C19-C22+C21-C23 -> 456423 | D24: =D19-D22+D21-D23 -> 550623 | E24: =E19-E22+E21-E23 -> 572916 | F24: =F19-F22+F21-F23 -> 747505 | G24: =G19-G22+G21-G23 -> 734288 | H24: =H19-H22+H21-H23 -> 1090991 | I24: =I19-I22+I21-I23 -> 1195951 | ... Q24: =Q19-Q22+Q21-Q23 -> 2356179
A26: Provision for income taxes | B26: 137273 | C26: 171051 | D26: 209134 | E26: 225233 | F26: 262603 | G26: 344815 | H26: 367000 | I26: 380945 | J26: 300268 | K26: 308127 | L26: 216563 | M26: 423944 | N26: 380340 | O26: 437494 | P26: 480411 | Q26: 577097
A27: Net income (loss) | B27: =B24-B26 -> 210541 | C27: =C24-C26 -> 285372 | D27: =D24-D26 -> 341489 | E27: =E24-E26 -> 347683 | F27: =F24-F26 -> 484902 | G27: =G24-G26 -> 389473 | H27: =H24-H26 -> 723991 | I27: =I24-I26 -> 815006 | ... Q27: =Q24-Q26 -> 1779082
A31: Monster-US
A32: Balance Sheet ($'000)
B33: 2010 | C33: =B33+1 -> 2011 | D33: =C33+1 -> 2012 | E33: =D33+1 -> 2013 | F33: =E33+1 -> 2014 | G33: =F33+1 -> 2015 | H33: =G33+1 -> 2016 | I33: =H33+1 -> 2017 | J33: =I33+1 -> 2018 | ... N33: =M33+1 -> 2022 | O33: 2023 | P33: =O33+1 -> 2024 | Q33: =P33+1 -> 2025
A34: Current assets
A35: Cash and cash equivalents | B35: 354842 | C35: 359331 | D35: 222514 | E35: 211349 | F35: 370323 | G35: 2175417 | H35: 377582 | I35: 528622 | J35: 637513 | K35: 797957 | L35: 1180413 | M35: 1326462 | N35: 1307141 | O35: 2297675 | P35: 1533287 | Q35: 2088117
A36: Short-term investments | B36: 244649 | C36: 411282 | D36: 97042 | E36: 402247 | F36: 781134 | G36: 744610 | H36: 220554 | I36: 672933 | J36: 320650 | K36: 533063 | L36: 881354 | M36: 1749727 | N36: 1362314 | O36: 955605 | P36: 0 | Q36: 677084
A37: Accounts receivable, net | B37: 101635 | C37: 218741 | D37: 236710 | E37: =291638+4542 -> 296180 | F37: =280203+552 -> 280755 | G37: =352955+125000 -> 477955 | H37: =448051+125000 -> 573051 | I37: 449476 | J37: 484562 | K37: 540330 | L37: 666012 | M37: 896658 | N37: 1016203 | O37: 1193964 | P37: 1221646 | Q37: 1618072
A38: Inventories | B38: 153241 | C38: 155613 | D38: 203106 | E38: 221449 | F38: 174573 | G38: 156121 | H38: 161971 | I38: 255745 | J38: 277705 | K38: 360731 | L38: 333085 | M38: 593357 | N38: 935631 | O38: 971406 | P38: 737107 | Q38: 799623
A39: Prepaid expenses and other current assets | B39: 17022 | C39: 20912 | D39: 24983 | E39: 21376 | F39: 19673 | G39: 26967 | H39: 32562 | I39: 40877 | J39: 44909 | K39: 54868 | L39: 55358 | M39: 82668 | N39: 109823 | O39: 116195 | P39: 107262 | Q39: 103551
A40: Intangibles held-for-sale | E40: 0 | F40: 18079 | G40: 0 | H40: 0
A41: Prepaid Income Taxes | B41: 9992 | C41: 370 | D41: 33709 | E41: 9518 | F41: 8617 | G41: 18462 | H41: 66550 | I41: 138724 | J41: 38831 | L41: 24733 | M41: 33238 | N41: 33785 | O41: 54151 | P41: 42202 | Q41: 74637
A42: Deferred income tax | B42: 16772 | C42: 16428 | D42: 17004 | E42: 20924 | F42: 40275 | G42: 0 | H42: 0
A43: Total current assets | B43: =B42+B39+B38+B37+B36+B35+B41+B40 -> 898153 | C43: =C42+C39+C38+C37+C36+C35+C41+C40 -> 1182677 | D43: =D42+D39+D38+D37+D36+D35+D41+D40 -> 835068 | E43: =E42+E39+E38+E37+E36+E35+E41+E40 -> 1183043 | F43: =F42+F39+F38+F37+F36+F35+F41+F40 -> 1693429 | G43: =G42+G39+G38+G37+G36+G35+G41+G40 -> 3599532 | H43: =H42+H39+H38+H37+H36+H35+H41+H40 -> 1432270 | I43: =I42+I39+I38+I37+I36+I35+I41+I40 -> 2086377 | ... Q43: =Q42+Q39+Q38+Q37+Q36+Q35+Q41+Q40 -> 5361084
A45: Long-term assets
A46: Investments | B46: 44189 | C46: 23194 | D46: 21393 | E46: 9792 | F46: 42940 | G46: 15348 | H46: 2394 | I46: 2366 | L46: 44291 | M46: 99419 | N46: 61443 | O46: 76431 | P46: 0 | Q46: 48329
A47: Property and equipment, net | B47: 34551 | C47: 45151 | D47: 69137 | E47: 88143 | F47: 90156 | G47: 97354 | H47: 173343 | I47: 230276 | J47: 243051 | K47: 298640 | L47: 314656 | M47: 313753 | N47: 516897 | O47: 890796 | P47: 1047024 | Q47: 1081544
A48: Deferred Income Taxes | B48: 58475 | C48: 58576 | D48: 59503 | E48: 63611 | F48: 54106 | G48: 140468 | H48: 159556 | I48: 92333 | J48: 85687 | L48: 241650 | M48: 225221 | N48: 177039 | O48: 175003 | P48: 184260 | Q48: 188646
A49: Intangible assets, net | B49: 43316 | C49: 48396 | D49: 54648 | E49: 65774 | F49: 50748 | G49: 427986 | H49: 1032635 | I49: 1034085 | J49: 1045878 | K49: 1052105 | L49: 1059046 | M49: 1072386 | N49: 1220410 | O49: 1427139 | P49: 1414252 | Q49: 1379268
...

Sheet Investment Analysis (1)
A1: Solvency and Net Asset Value (NAV)
A2: Investment Performance Ratio (Market ratios)
A3: Sustainable Growth Rate (SGR)
A4: Du Pont Analysis
A6: Monster-US
A7: Income Statement ($'000)
B8: 2010 | C8: =B8+1 -> 2011 | D8: =C8+1 -> 2012 | E8: =D8+1 -> 2013 | F8: =E8+1 -> 2014 | G8: =F8+1 -> 2015 | H8: =G8+1 -> 2016 | I8: =H8+1 -> 2017 | J8: =I8+1 -> 2018 | ... N8: =M8+1 -> 2022 | O8: FY2023A | P8: FY2024A | Q8: FY2025A
A9: Net sales | B9: 1303942 | C9: 1703230 | D9: 2060702 | E9: 2246428 | F9: 2464867 | G9: 2722564 | H9: 3049393 | I9: 3369045 | J9: 3807183 | K9: 4200819 | L9: 4598638 | M9: 5541352 | N9: 6311050 | O9: 7140027 | P9: 7492709 | Q9: 8294343
A10: Cost of sales | B10: 623702 | C10: 808921 | D10: 995046 | E10: 1073497 | F10: 1125057 | G10: 1090263 | H10: 1107393 | I10: 1231355 | J10: 1511808 | K10: 1682234 | L10: 1874758 | M10: 2432839 | N10: 3136483 | O10: 3345821 | P10: 3443831 | Q10: 3662148
A11: Gross profit | B11: =B9-B10 -> 680240 | C11: =C9-C10 -> 894309 | D11: =D9-D10 -> 1065656 | E11: =E9-E10 -> 1172931 | F11: =F9-F10 -> 1339810 | G11: =G9-G10 -> 1632301 | H11: =H9-H10 -> 1942000 | I11: =I9-I10 -> 2137690 | ... Q11: =Q9-Q10 -> 4632195
A13: Selling, general and administrative | B13: 0 | C13: 0 | D13: 0 | E13: 0 | F13: 0 | G13: 0 | H13: 0 | I13: 0 | J13: 0 | K13: 0 | L13: 0 | M13: 0 | N13: 0 | O13: 0 | P13: 0 | Q13: 0
A14: Freight-Out-Cots | B14: 47400 | C14: 60500 | D14: 76100 | E14: 84000 | F14: 92700 | G14: 87000 | H14: 83600 | I14: 91900 | J14: 128500 | K14: 122500 | L14: 134100 | M14: 213900 | N14: 249200 | O14: 223600 | P14: 224200 | Q14: 237000
A15: Advertising and Promotional | B15: 104900 | C15: 148800 | D15: 165400 | E15: 181800 | F15: 171500 | G15: 209700 | H15: 270600 | I15: 324000 | J15: 353900 | K15: 391600 | L15: 345700 | M15: 417600 | N15: 460700 | O15: 528900 | P15: 584100 | Q15: 599900
A16: Other Expenses | B16: 180126 | C16: 228586 | D16: 273533 | E16: 334215 | F16: 328105 | G16: 603418 | H16: 502462 | I16: 523003 | J16: 529356 | K16: 601546 | L16: 610927 | M16: 679546 | N16: 879946 | O16: 1088351 | P16: 1310284 | Q16: 1375941
A17: Total Operating expenses | B17: =B16+B15+B14+B13 -> 332426 | C17: =C16+C15+C14+C13 -> 437886 | D17: =D16+D15+D14+D13 -> 515033 | E17: =E16+E15+E14+E13 -> 600015 | F17: =F16+F15+F14+F13 -> 592305 | G17: =G16+G15+G14+G13 -> 900118 | H17: =H16+H15+H14+H13 -> 856662 | I17: =I16+I15+I14+I13 -> 938903 | ... Q17: =Q16+Q15+Q14+Q13 -> 2212841
A18: Operating income (loss) | B18: =B11-B17 -> 347814 | C18: =C11-C17 -> 456423 | D18: =D11-D17 -> 550623 | E18: =E11-E17 -> 572916 | F18: =F11-F17 -> 747505 | G18: =G11-G17 -> 732183 | H18: =H11-H17 -> 1085338 | I18: =I11-I17 -> 1198787 | ... Q18: =Q11-Q17 -> 2419354
A20: Interest income | B20: 0 | C20: 0 | D20: 0 | E20: 0 | F20: 0 | G20: 0 | H20: 0 | I20: 0 | J20: 0 | K20: 0 | L20: 0 | M20: 0 | N20: 0 | O20: 0 | P20: 0 | Q20: 0
A21: Interest expense | B21: 0 | C21: 0 | D21: 0 | E21: 0 | F21: 0 | G21: 0 | H21: 0 | I21: 0 | J21: 0 | K21: 0 | L21: 0 | M21: 0 | N21: 0 | O21: 0 | P21: 0 | Q21: 0
A22: Other income (expense), net | B22: 0 | C22: 0 | D22: 0 | E22: 0 | F22: 0 | G22: -2105 | H22: -5653 | I22: 2836 | J22: 9653 | K22: 13023 | L22: -6996 | M22: 3952 | N22: -12757 | O22: 115127 | P22: 59165 | Q22: 63175
A23: Income before income taxes | B23: =B18-B21+B20-B22 -> 347814 | C23: =C18-C21+C20-C22 -> 456423 | D23: =D18-D21+D20-D22 -> 550623 | E23: =E18-E21+E20-E22 -> 572916 | F23: =F18-F21+F20-F22 -> 747505 | G23: =G18-G21+G20-G22 -> 734288 | H23: =H18-H21+H20-H22 -> 1090991 | I23: =I18-I21+I20-I22 -> 1195951 | ... Q23: =Q18-Q21+Q20-Q22 -> 2356179
A25: Provision for income taxes | B25: 137273 | C25: 171051 | D25: 209134 | E25: 225233 | F25: 262603 | G25: 344815 | H25: 367000 | I25: 380945 | J25: 300268 | K25: 308127 | L25: 216563 | M25: 423944 | N25: 380340 | O25: 437494 | P25: 480411 | Q25: 577097
A26: Net income (loss) | B26: =B23-B25 -> 210541 | C26: =C23-C25 -> 285372 | D26: =D23-D25 -> 341489 | E26: =E23-E25 -> 347683 | F26: =F23-F25 -> 484902 | G26: =G23-G25 -> 389473 | H26: =H23-H25 -> 723991 | I26: =I23-I25 -> 815006 | ... Q26: =Q23-Q25 -> 1779082
A28: Basic weighted average shares | B28: 88514 | C28: 176212 | D28: 173712 | E28: 166679 | F28: 167257 | G28: 188816 | H28: 587874 | I28: 566782 | J28: 557166 | K28: 542191 | L28: 529639 | M28: 528763 | N28: 1053558 | O28: 1044887 | P28: 1004566 | Q28: =975887*2 -> 1951774
A29: Diluted weighted average shares | B29: 93021 | C29: 186674 | D29: 183083 | E29: 173387 | F29: 174285 | G29: 192586 | H29: 599819 | I29: 577141 | J29: 564254 | K29: 546608 | L29: 534807 | M29: 535639 | N29: 1066442 | O29: 1057981 | P29: 1013107 | Q29: =984451*2 -> 1968902
A31: Monster-US
A32: Balance Sheet ($'000)
B33: 2010 | C33: =B33+1 -> 2011 | D33: =C33+1 -> 2012 | E33: =D33+1 -> 2013 | F33: =E33+1 -> 2014 | G33: =F33+1 -> 2015 | H33: =G33+1 -> 2016 | I33: =H33+1 -> 2017 | J33: =I33+1 -> 2018 | ... N33: =M33+1 -> 2022 | O33: 2023 | P33: =O33+1 -> 2024 | Q33: =P33+1 -> 2025
A34: Current assets
A35: Cash and cash equivalents | B35: 354842 | C35: 359331 | D35: 222514 | E35: 211349 | F35: 370323 | G35: 2175417 | H35: 377582 | I35: 528622 | J35: 637513 | K35: 797957 | L35: 1180413 | M35: 1326462 | N35: 1307141 | O35: 2297675 | P35: 1533287 | Q35: 2088117
A36: Short-term investments | B36: 244649 | C36: 411282 | D36: 97042 | E36: 402247 | F36: 781134 | G36: 744610 | H36: 220554 | I36: 672933 | J36: 320650 | K36: 533063 | L36: 881354 | M36: 1749727 | N36: 1362314 | O36: 955605 | P36: 0 | Q36: 677084
A37: Accounts receivable, net | B37: 101635 | C37: 218741 | D37: 236710 | E37: =291638+4542 -> 296180 | F37: =280203+552 -> 280755 | G37: =352955+125000 -> 477955 | H37: =448051+125000 -> 573051 | I37: 449476 | J37: 484562 | K37: 540330 | L37: 666012 | M37: 896658 | N37: 1016203 | O37: 1193964 | P37: 1221646 | Q37: 1618072
A38: Inventories | B38: 153241 | C38: 155613 | D38: 203106 | E38: 221449 | F38: 174573 | G38: 156121 | H38: 161971 | I38: 255745 | J38: 277705 | K38: 360731 | L38: 333085 | M38: 593357 | N38: 935631 | O38: 971406 | P38: 737107 | Q38: 799623
A39: Prepaid expenses and other current assets | B39: 17022 | C39: 20912 | D39: 24983 | E39: 21376 | F39: 19673 | G39: 26967 | H39: 32562 | I39: 40877 | J39: 44909 | K39: 54868 | L39: 55358 | M39: 82668 | N39: 109823 | O39: 116195 | P39: 107262 | Q39: 103551
A40: Intangibles held-for-sale | E40: 0 | F40: 18079 | G40: 0 | H40: 0
A41: Prepaid Income Taxes | B41: 9992 | C41: 370 | D41: 33709 | E41: 9518 | F41: 8617 | G41: 18462 | H41: 66550 | I41: 138724 | J41: 38831 | L41: 24733 | M41: 33238 | N41: 33785 | O41: 54151 | P41: 42202 | Q41: 74637
A42: Deferred income tax | B42: 16772 | C42: 16428 | D42: 17004 | E42: 20924 | F42: 40275 | G42: 0 | H42: 0
A43: Total current assets | B43: =B42+B39+B38+B37+B36+B35+B41+B40 -> 898153 | C43: =C42+C39+C38+C37+C36+C35+C41+C40 -> 1182677 | D43: =D42+D39+D38+D37+D36+D35+D41+D40 -> 835068 | E43: =E42+E39+E38+E37+E36+E35+E41+E40 -> 1183043 | F43: =F42+F39+F38+F37+F36+F35+F41+F40 -> 1693429 | G43: =G42+G39+G38+G37+G36+G35+G41+G40 -> 3599532 | H43: =H42+H39+H38+H37+H36+H35+H41+H40 -> 1432270 | I43: =I42+I39+I38+I37+I36+I35+I41+I40 -> 2086377 | ... Q43: =Q42+Q39+Q38+Q37+Q36+Q35+Q41+Q40 -> 5361084
A45: Long-term assets
A46: Investments | B46: 44189 | C46: 23194 | D46: 21393 | E46: 9792 | F46: 42940 | G46: 15348 | H46: 2394 | I46: 2366 | L46: 44291 | M46: 99419 | N46: 61443 | O46: 76431 | P46: 0 | Q46: 48329
A47: Property and equipment, net | B47: 34551 | C47: 45151 | D47: 69137 | E47: 88143 | F47: 90156 | G47: 97354 | H47: 173343 | I47: 230276 | J47: 243051 | K47: 298640 | L47: 314656 | M47: 313753 | N47: 516897 | O47: 890796 | P47: 1047024 | Q47: 1081544
...

Sheet Monster Consolidated Statements
A1: Monster Beverage Corporation - Historical Financial Statements
A2: USD in $'000
A3: 1994 | B3: 1994 | C3: =B3+1 -> 1995 | D3: =C3+1 -> 1996 | E3: =D3+1 -> 1997 | F3: =E3+1 -> 1998 | G3: =F3+1 -> 1999 | H3: =G3+1 -> 2000 | I3: =H3+1 -> 2001 | J3: =I3+1 -> 2002 | ... AG3: =AF3+1 -> 2025
A5: INCOME STATEMENT | AI5: 31yr | AJ5: Check | AL5: 20yr | AM5: Check | AO5: 10yr | AP5: Check | AR5: 5yr | AS5: Check
A6: Net sales | B6: 28815.522 | C6: 33990.675 | D6: 35565.485 | E6: 43057.064 | F6: 53866.294 | G6: 72303.186 | H6: 79732.709 | I6: 92279.711 | J6: 92046.362 | K6: 110352.2 | L6: 180341.14 | M6: 348886.37 | N6: 605774 | O6: 904465 | P6: 1033780 | Q6: 1143299 | R6: 1303942 | S6: 1703230 | T6: 2060702 | U6: 2246428 | V6: 2464867 | W6: 2722564 | X6: 3049393 | Y6: 3369045 | Z6: 3807183 | AA6: 4200819 | AB6: 4598638 | AC6: 5541352 | AD6: 6311050 | AE6: 7140027 | AF6: 7492709 | AG6: 8294343 | AI6: =IFERROR((AG6/B6)^(1/31)-1,"") -> 0.20040445 | AJ6: =IFERROR(PRODUCT(1+C7,1+D7,1+E7,1+F7,1+G7,1+H7,1+I7,1+J7,1+K7,1+L7,1+M7,1+N7,1+O7,1+P7,1+Q7,1+R7,1+S7,1+T7,1+U7,1+V7,1+W7,1+X7,1+Y7,1+Z7,1+AA7,1+AB7,1+AC7,1+AD7,1+AE7,1+AF7,1+AG7)^(1/31)-1,"") -> 0.20040445 | AL6: =IFERROR((AG6/M6)^(1/20)-1,"") -> 0.17166889 | AM6: =IFERROR(PRODUCT(1+N7,1+O7,1+P7,1+Q7,1+R7,1+S7,1+T7,1+U7,1+V7,1+W7,1+X7,1+Y7,1+Z7,1+AA7,1+AB7,1+AC7,1+AD7,1+AE7,1+AF7,1+AG7)^(1/20)-1,"") -> 0.17166889 | AO6: =IFERROR((AG6/W6)^(1/10)-1,"") -> 0.11784191 | AP6: =IFERROR(PRODUCT(1+X7,1+Y7,1+Z7,1+AA7,1+AB7,1+AC7,1+AD7,1+AE7,1+AF7,1+AG7)^(1/10)-1,"") -> 0.11784191 | AR6: =IFERROR((AG6/AB6)^(1/5)-1,"") -> 0.12520215 | AS6: =IFERROR(PRODUCT(1+AC7,1+AD7,1+AE7,1+AF7,1+AG7)^(1/5)-1,"") -> 0.12520215
A7: % Growth | C7: =IFERROR((C6/B6-1),"") -> 0.17959602 | D7: =IFERROR((D6/C6-1),"") -> 0.046330648 | E7: =IFERROR((E6/D6-1),"") -> 0.21064183 | F7: =IFERROR((F6/E6-1),"") -> 0.25104429 | G7: =IFERROR((G6/F6-1),"") -> 0.3422714 | H7: =IFERROR((H6/G6-1),"") -> 0.10275513 | I7: =IFERROR((I6/H6-1),"") -> 0.1573633 | J7: =IFERROR((J6/I6-1),"") -> -0.002528714 | ... AG7: =IFERROR((AG6/AF6-1),"") -> 0.10698854 | AI7: 31yr | AJ7: Check | AL7: 20yr | AM7: Check | AO7: 10yr | AP7: Check | AR7: 5yr | AS7: Check
A8: Cost of sales | B8: 15886.142 | C8: 21855.369 | D8: 21671.064 | E8: 25222.881 | F8: 27332.028 | G8: 38776.532 | H8: 42646.677 | I8: 51455.207 | J8: 58802.669 | K8: 66577.168 | L8: 96874.75 | M8: 166343.12 | N8: 289180 | O8: 436452 | P8: 494986 | Q8: 530983 | R8: 623702 | S8: 808921 | T8: 995046 | U8: 1073497 | V8: 1125057 | W8: 1090263 | X8: 1107393 | Y8: 1231355 | Z8: 1511808 | AA8: 1682234 | AB8: 1874758 | AC8: 2432839 | AD8: 3136483 | AE8: 3345821 | AF8: 3443831 | AG8: 3662148 | AI8: =IFERROR((AG8/B8)^(1/31)-1,"") -> 0.19183653 | AJ8: =IFERROR(PRODUCT(1+C9,1+D9,1+E9,1+F9,1+G9,1+H9,1+I9,1+J9,1+K9,1+L9,1+M9,1+N9,1+O9,1+P9,1+Q9,1+R9,1+S9,1+T9,1+U9,1+V9,1+W9,1+X9,1+Y9,1+Z9,1+AA9,1+AB9,1+AC9,1+AD9,1+AE9,1+AF9,1+AG9)^(1/31)-1,"") -> 0.19183653 | AL8: =IFERROR((AG8/M8)^(1/20)-1,"") -> 0.16717655 | AM8: =IFERROR(PRODUCT(1+N9,1+O9,1+P9,1+Q9,1+R9,1+S9,1+T9,1+U9,1+V9,1+W9,1+X9,1+Y9,1+Z9,1+AA9,1+AB9,1+AC9,1+AD9,1+AE9,1+AF9,1+AG9)^(1/20)-1,"") -> 0.16717655 | AO8: =IFERROR((AG8/W8)^(1/10)-1,"") -> 0.128809 | AP8: =IFERROR(PRODUCT(1+X9,1+Y9,1+Z9,1+AA9,1+AB9,1+AC9,1+AD9,1+AE9,1+AF9,1+AG9)^(1/10)-1,"") -> 0.128809 | AR8: =IFERROR((AG8/AB8)^(1/5)-1,"") -> 0.14329456 | AS8: =IFERROR(PRODUCT(1+AC9,1+AD9,1+AE9,1+AF9,1+AG9)^(1/5)-1,"") -> 0.14329456
A9: % Growth | C9: =IFERROR((C8/B8-1),"") -> 0.37575058 | D9: =IFERROR((D8/C8-1),"") -> -0.0084329393 | E9: =IFERROR((E8/D8-1),"") -> 0.16389675 | F9: =IFERROR((F8/E8-1),"") -> 0.083620384 | G9: =IFERROR((G8/F8-1),"") -> 0.41872136 | H9: =IFERROR((H8/G8-1),"") -> 0.099806373 | I9: =IFERROR((I8/H8-1),"") -> 0.20654669 | J9: =IFERROR((J8/I8-1),"") -> 0.14279336 | ... AG9: =IFERROR((AG8/AF8-1),"") -> 0.063393645
A10: Gross profit | B10: =B6-B8 -> 12929.38 | C10: =C6-C8 -> 12135.306 | D10: =D6-D8 -> 13894.421 | E10: =E6-E8 -> 17834.183 | F10: =F6-F8 -> 26534.266 | G10: =G6-G8 -> 33526.654 | H10: =H6-H8 -> 37086.032 | I10: =I6-I8 -> 40824.504 | ... AG10: =AG6-AG8 -> 4632195
A11: % of Revenue | B11: =B10/$B$6 -> 0.44869498 | C11: =C10/C6 -> 0.35701868 | D11: =D10/D6 -> 0.39067149 | E11: =E10/E6 -> 0.41419877 | F11: =F10/F6 -> 0.49259498 | G11: =G10/G6 -> 0.46369539 | H11: =H10/H6 -> 0.46512946 | I11: =I10/I6 -> 0.44239956 | J11: =J10/J6 -> 0.36116249 | ... AG11: =AG10/AG6 -> 0.55847642
A13: Selling, general and administrative | B13: 13117.979 | C13: 12506.77 | D13: 12524.85 | E13: 15452.188 | F13: 20217.818 | G13: 25337.374 | H13: 29814.609 | I13: 34766.159 | J13: 27896.202 | K13: 33887.045 | L13: 49507.137 | M13: 79029.837 | N13: 0 | O13: 0 | P13: 0 | Q13: 0 | R13: 0 | S13: 0 | T13: 0 | U13: 0 | V13: 0 | W13: 0 | X13: 0 | Y13: 0 | Z13: 0 | AA13: 0 | AB13: 0 | AC13: 0 | AD13: 0 | AE13: 0 | AF13: 0 | AG13: 0
A14: % Growth | C14: =IFERROR((C13/B13-1),"") -> -0.046593229 | D14: =IFERROR((D13/C13-1),"") -> 0.0014456171 | E14: =IFERROR((E13/D13-1),"") -> 0.2337224 | F14: =IFERROR((F13/E13-1),"") -> 0.30841134 | G14: =IFERROR((G13/F13-1),"") -> 0.25322001 | H14: =IFERROR((H13/G13-1),"") -> 0.17670478 | I14: =IFERROR((I13/H13-1),"") -> 0.16607798 | J14: =IFERROR((J13/I13-1),"") -> -0.19760472 | ... AG14: =IFERROR((AG13/AF13-1),"")
A15: Freight-Out-Cots | N15: 36200 | O15: 40800 | P15: 45100 | Q15: 39800 | R15: 47400 | S15: 60500 | T15: 76100 | U15: 84000 | V15: 92700 | W15: 87000 | X15: 83600 | Y15: 91900 | Z15: 128500 | AA15: 122500 | AB15: 134100 | AC15: 213900 | AD15: 249200 | AE15: 223600 | AF15: 224200 | AG15: 237000
A16: % Growth
A17: Advertising and Promotional | N17: 35700 | O17: 66600 | P17: 84600 | Q17: 86700 | R17: 104900 | S17: 148800 | T17: 165400 | U17: 181800 | V17: 171500 | W17: 209700 | X17: 270600 | Y17: 324000 | Z17: 353900 | AA17: 391600 | AB17: 345700 | AC17: 417600 | AD17: 460700 | AE17: 528900 | AF17: 584100 | AG17: 599900
A18: % Growth
A19: Other Expenses | B19: 998.833 | C19: 935.244 | D19: 692.624 | E19: 500.086 | F19: 356.582 | G19: 688.226 | H19: 371.091 | I19: 507.441 | J19: 54.598 | K19: 61.855 | L19: 73.063 | M19: 70.063 | N19: 86115 | O19: 129627 | P19: 245503 | Q19: 148507 | R19: 180126 | S19: 228586 | T19: 273533 | U19: 334215 | V19: 328105 | W19: 603418 | X19: 502462 | Y19: 523003 | Z19: 529356 | AA19: 601546 | AB19: 610927 | AC19: 679546 | AD19: 879946 | AE19: 1088351 | AF19: 1310284 | AG19: 1375941
A20: % Growth | AI20: 31yr | AJ20: Check | AL20: 20yr | AM20: Check | AO20: 10yr | AP20: Check | AR20: 5yr | AS20: Check
A21: Total Operating expenses | B21: =B19+B13 -> 14116.812 | C21: =C19+C13 -> 13442.014 | D21: =D19+D13 -> 13217.474 | E21: =E19+E13 -> 15952.274 | F21: =F19+F13 -> 20574.4 | G21: =G19+G13 -> 26025.6 | H21: =H19+H13 -> 30185.7 | I21: =I19+I13 -> 35273.6 | ... M21: =M19+M13 -> 79099.9 | N21: =N19+N17+N15+N13 -> 158015 | O21: =O19+O17+O15+O13 -> 237027 | P21: =P19+P17+P15+P13 -> 375203 | Q21: =Q19+Q17+Q15+Q13 -> 275007 | R21: =R19+R17+R15+R13 -> 332426 | S21: =S19+S17+S15+S13 -> 437886 | T21: =T19+T17+T15+T13 -> 515033 | U21: =U19+U17+U15+U13 -> 600015 | ... AG21: =AG19+AG17+AG15+AG13 -> 2212841 | AI21: =IFERROR((AG21/B21)^(1/31)-1,"") -> 0.17709995 | AJ21: =IFERROR(PRODUCT(1+C22,1+D22,1+E22,1+F22,1+G22,1+H22,1+I22,1+J22,1+K22,1+L22,1+M22,1+N22,1+O22,1+P22,1+Q22,1+R22,1+S22,1+T22,1+U22,1+V22,1+W22,1+X22,1+Y22,1+Z22,1+AA22,1+AB22,1+AC22,1+AD22,1+AE22,1+AF22,1+AG22)^(1/31)-1,"") -> 0.17709995 | AL21: =IFERROR((AG21/M21)^(1/20)-1,"") -> 0.18124155 | AM21: =IFERROR(PRODUCT(1+N22,1+O22,1+P22,1+Q22,1+R22,1+S22,1+T22,1+U22,1+V22,1+W22,1+X22,1+Y22,1+Z22,1+AA22,1+AB22,1+AC22,1+AD22,1+AE22,1+AF22,1+AG22)^(1/20)-1,"") -> 0.18124155 | AO21: =IFERROR((AG21/W21)^(1/10)-1,"") -> 0.094120301 | AP21: =IFERROR(PRODUCT(1+X22,1+Y22,1+Z22,1+AA22,1+AB22,1+AC22,1+AD22,1+AE22,1+AF22,1+AG22)^(1/10)-1,"") -> 0.094120301 | AR21: =IFERROR((AG21/AB21)^(1/5)-1,"") -> 0.15198501 | AS21: =IFERROR(PRODUCT(1+AC22,1+AD22,1+AE22,1+AF22,1+AG22)^(1/5)-1,"") -> 0.15198501
A22: % Growth | C22: =IFERROR((C21/B21-1),"") -> -0.047801019 | D22: =IFERROR((D21/C21-1),"") -> -0.016704342 | E22: =IFERROR((E21/D21-1),"") -> 0.20690792 | F22: =IFERROR((F21/E21-1),"") -> 0.28974715 | G22: =IFERROR((G21/F21-1),"") -> 0.26495062 | H22: =IFERROR((H21/G21-1),"") -> 0.15984646 | I22: =IFERROR((I21/H21-1),"") -> 0.16855332 | J22: =IFERROR((J21/I21-1),"") -> -0.20760002 | ... AG22: =IFERROR((AG21/AF21-1),"") -> 0.044490565
A23: Operating income (loss) | B23: =B10-B21 -> -1187.432 | C23: =C10-C21 -> -1306.708 | D23: =D10-D21 -> 676.947 | E23: =E10-E21 -> 1881.909 | F23: =F10-F21 -> 5959.866 | G23: =G10-G21 -> 7501.054 | H23: =H10-H21 -> 6900.332 | I23: =I10-I21 -> 5550.904 | ... AG23: =AG10-AG21 -> 2419354
A24: % of Revenue | B24: =-B23/B$6 -> 0.041208068 | C24: =-C23/C$6 -> 0.038443132 | D24: =D23/D$6 -> 0.019033819 | E24: =E23/E$6 -> 0.043707323 | F24: =F23/F$6 -> 0.11064184 | G24: =G23/G$6 -> 0.10374445 | H24: =H23/H$6 -> 0.086543303 | I24: =I23/I$6 -> 0.060153028 | J24: =J23/J$6 -> 0.057502468 | K24: =K23/K$6 -> 0.089043339 | ... AG24: =AG23/AG$6 -> 0.29168724
A26: Interest income | B26: -58.325 | C26: -19.725 | D26: -8.919 | E26: -3.481 | F26: -72.352 | G26: -118.413 | H26: -12.914 | I26: -8.992 | J26: -2.974 | K26: 0 | L26: 0 | M26: 1427.803 | N26: 3660 | O26: 8770 | P26: 0 | Q26: 0 | R26: 0 | S26: 0 | T26: 0 | U26: 0 | V26: 0 | W26: 0 | X26: 0 | Y26: 0 | Z26: 0 | AA26: 0 | AB26: 0 | AC26: 0 | AD26: 0 | AE26: 0 | AF26: 0 | AG26: 0
A27: Interest expense | B27: 344.923 | C27: 459.542 | D27: 585.733 | E27: 525.294 | F27: 387.446 | G27: 170.506 | H27: 382.152 | I27: 527.594 | J27: 230.732 | K27: 72.592 | L27: 41.988 | M27: -76.531 | N27: 0 | O27: 0 | P27: 0 | Q27: 0 | R27: 0 | S27: 0 | T27: 0 | U27: 0 | V27: 0 | W27: 0 | X27: 0 | Y27: 0 | Z27: 0 | AA27: 0 | AB27: 0 | AC27: 0 | AD27: 0 | AE27: 0 | AF27: 0 | AG27: 0
A28: Other income (expense), net | B28: -28.766 | C28: -399.232 | D28: -259.433 | E28: 69.745 | F28: 14.719 | G28: 0 | H28: 0 | I28: 0 | J28: 0 | K28: 0 | L28: 0 | M28: 0 | N28: 0 | O28: 0 | P28: 0 | Q28: 0 | R28: 0 | S28: 0 | T28: 0 | U28: 0 | V28: 0 | W28: -2105 | X28: -5653 | Y28: 2836 | Z28: 9653 | AA28: 13023 | AB28: -6996 | AC28: 3952 | AD28: -12757 | AE28: 115127 | AF28: 59165 | AG28: 63175
A29: Income before income taxes | B29: =B23-B27+B26-B28 -> -1561.914 | C29: =C23-C27+C26-C28 -> -1386.743 | D29: =D23-D27+D26-D28 -> 341.728 | E29: =E23-E27+E26-E28 -> 1283.389 | F29: =F23-F27+F26-F28 -> 5485.349 | G29: =G23-G27+G26-G28 -> 7212.135 | H29: =H23-H27+H26-H28 -> 6505.266 | I29: =I23-I27+I26-I28 -> 5014.318 | ... AG29: =AG23-AG27+AG26-AG28 -> 2356179
A30: % of Revenue | B30: =-B29/B$6 -> 0.054203911 | C30: =-C29/C$6 -> 0.040797748 | D30: =D29/D$6 -> 0.0096084167 | E30: =E29/E$6 -> 0.0298067 | F30: =F29/F$6 -> 0.10183268 | G30: =G29/G$6 -> 0.099748509 | H30: =H29/H$6 -> 0.081588423 | I30: =I29/I$6 -> 0.05433825 | J30: =J29/J$6 -> 0.054963465 | K30: =K29/K$6 -> 0.088385518 | ... AG30: =AG29/AG$6 -> 0.2840706
A32: Provision for income taxes | B32: -37.917 | C32: 2.4 | D32: 2.4 | E32: 40.2 | F32: 2066.922 | G32: 2971.118 | H32: 2615.986 | I32: 2012.902 | J32: 2035.98 | K32: 3823.099 | L32: 13457.41 | M32: 39316.061 | N32: 64290 | O32: 90350 | P32: 65445 | Q32: 126979 | R32: 137273 | S32: 171051 | T32: 209134 | U32: 225233 | V32: 262603 | W32: 344815 | X32: 367000 | Y32: 380945 | Z32: 300268 | AA32: 308127 | AB32: 216563 | AC32: 423944 | AD32: 380340 | AE32: 437494 | AF32: 480411 | AG32: 577097
A33: Net income (loss) | B33: =B29-B32 -> -1523.997 | C33: =C29-C32 -> -1389.143 | D33: =D29-D32 -> 339.328 | E33: =E29-E32 -> 1243.189 | F33: =F29-F32 -> 3418.427 | G33: =G29-G32 -> 4241.017 | H33: =H29-H32 -> 3889.28 | I33: =I29-I32 -> 3001.416 | ... AG33: =AG29-AG32 -> 1779082
A34: % of Revenue | B34: =-B33/B$6 -> 0.052888058 | C34: =-C33/C$6 -> 0.040868356 | D34: =D33/D$6 -> 0.0095409355 | E34: =E33/E$6 -> 0.028873056 | F34: =F33/F$6 -> 0.063461336 | G34: =G33/G$6 -> 0.058656018 | H34: =H33/H$6 -> 0.048778977 | I34: =I33/I$6 -> 0.032525199 | J34: =J33/J$6 -> 0.032844394 | K34: =K33/K$6 -> 0.053740997 | ... AG34: =AG33/AG$6 -> 0.21449342
A36: Basic EPS | B36: =IFERROR(B33/B41,"") -> -0.1670524 | C36: =IFERROR(C33/C41,"") -> -0.15227043 | D36: =IFERROR(D33/D41,"") -> 0.036811995 | E36: =IFERROR(E33/E41,"") -> 0.13623048 | F36: =IFERROR(F33/F41,"") -> 0.36417819 | G36: =IFERROR(G33/G41,"") -> 0.42560075 | H36: =IFERROR(H33/H41,"") -> 0.39057847 | I36: =IFERROR(I33/I41,"") -> 0.29904867 | ... AG36: =IFERROR(AG33/AG41,"") -> 1.823041
A37: Diluted EPS | B37: =IFERROR(B33/B42,"") -> -0.1670524 | C37: =IFERROR(C33/C42,"") -> -0.15227043 | D37: =IFERROR(D33/D42,"") -> 0.036811995 | E37: =IFERROR(E33/E42,"") -> 0.13383969 | F37: =IFERROR(F33/F42,"") -> 0.32772663 | G37: =IFERROR(G33/G42,"") -> 0.40349889 | H37: =IFERROR(H33/H42,"") -> 0.37376427 | I37: =IFERROR(I33/I42,"") -> 0.29097857 | ... AG37: =IFERROR(AG33/AG42,"") -> 1.8071819
A38: % Growth | C38: =C36/B36-1 -> -0.088487051 | D38: =D36/C36-1 -> -1.2417541 | E38: =E36/D36-1 -> 2.7007091 | F38: =F36/E36-1 -> 1.6732503 | G38: =G36/F36-1 -> 0.16866075 | H38: =H36/G36-1 -> -0.082289055 | I38: =I36/H36-1 -> -0.23434421 | J38: =J36/I36-1 -> 0.0056618497 | ... AG38: =AG36/AF36-1 -> 0.31684856
A39: % Growth | C39: =C37/B37-1 -> -0.088487051 | D39: =D37/C37-1 -> -1.2417541 | E39: =E37/D37-1 -> 2.6357631 | F39: =F37/E37-1 -> 1.4486505 | G39: =G37/F37-1 -> 0.23120567 | H39: =H37/G37-1 -> -0.073691936 | I39: =I37/H37-1 -> -0.22149175 | J39: =J37/I37-1 -> 0.0048540231 | ... AG39: =AG37/AF37-1 -> 0.31649163
A41: Basic weighted average shares | B41: 9122.868 | C41: 9122.868 | D41: 9217.865 | E41: 9125.63 | F41: 9386.688 | G41: 9964.778 | H41: 9957.743 | I41: 10036.547 | J41: 10052.499 | K41: 10278.71 | L41: 84945.017 | M41: 88416.868 | N41: 89936 | O41: 91178 | P41: 92515 | Q41: 89967 | R41: 88514 | S41: 176212 | T41: 173712 | U41: 166679 | V41: 167257 | W41: 188816 | X41: 587874 | Y41: 566782 | Z41: 557166 | AA41: 542191 | AB41: 529639 | AC41: 528763 | AD41: 1053558 | AE41: 1044887 | AF41: 1004566 | AG41: 975887
A42: Diluted weighted average shares | B42: 9122.868 | C42: 9122.868 | D42: 9217.865 | E42: 9288.642 | F42: 10430.727 | G42: 10510.604 | H42: 10405.703 | I42: 10314.904 | J42: 10339.604 | K42: 10762.157 | L42: 92667.291 | M42: 96578.425 | N42: 98586 | O42: 98874 | P42: 97530 | Q42: 94643 | R42: 93021 | S42: 186674 | T42: 183083 | U42: 173387 | V42: 174285 | W42: 192586 | X42: 599819 | Y42: 577141 | Z42: 564254 | AA42: 546608 | AB42: 534807 | AC42: 535639 | AD42: 1066442 | AE42: 1057981 | AF42: 1013107 | AG42: 984451
A47: BALANCE SHEET
A48: Current assets
A49: Cash and cash equivalents | C49: 87.916 | D49: 186.931 | E49: 395.231 | F49: 3806.089 | G49: 2009.155 | H49: 130.665 | I49: 247.657 | J49: 537.92 | K49: 1098.785 | L49: 20976.119 | M49: 61654.284 | N49: 35129 | O49: 12440 | P49: 256801 | Q49: 328349 | R49: 354842 | S49: 359331 | T49: 222514 | U49: 211349 | V49: 370323 | W49: 2175417 | X49: 377582 | Y49: 528622 | Z49: 637513 | AA49: 797957 | AB49: 1180413 | AC49: 1326462 | AD49: 1307141 | AE49: 2297675 | AF49: 1533287 | AG49: 2088117
A50: Short-term investments | M50: 11860.665 | N50: 101667 | O50: 63125 | P50: 29145 | Q50: 18487 | R50: 244649 | S50: 411282 | T50: 97042 | U50: 402247 | V50: 781134 | W50: 744610 | X50: 220554 | Y50: 672933 | Z50: 320650 | AA50: 533063 | AB50: 881354 | AC50: 1749727 | AD50: 1362314 | AE50: 955605 | AF50: 0 | AG50: 677084
...

Sheet Monster Investment Analysis (2)
