Workbook

Sheet Link
A1: https://investors.monsterbevcorp.com/financial-information/sec-filings?field_nir_sec_form_group_target_id%5B%5D=471&field_nir_sec_date_filed_value=&filter_type=&relative_date_range_after=&relative_date_range_before=&exact_date_range_after=&exact_date_range_before=#views-exposed-form-widget-sec-filings-table#views-exposed-form-widget-sec-filings-table
A2: To view the “Monster DCF” without errors, go to File → Settings → Calculation → Iterative Calculation, turn it On, and set the number of iterations to 100.

Sheet I.S
A1: ($'000, except for earnings per share) | B1: 2021 | C1: 2022 | D1: 2023 | E1: =D1+1 -> 2024 | F1: =E1+1 -> 2025 | G1: =F1+1 -> 2026 | H1: =G1+1 -> 2027 | I1: =H1+1 -> 2028 | J1: =I1+1 -> 2029 | K1: =J1+1 -> 2030 | N1: 4yr
A2: Revenue | B2: 5541352 | C2: 6311050 | D2: 7140027 | E2: 7492709 | F2: 8294343 | G2: =F2*(G3+1) -> 9264781.1 | H2: =G2*(H3+1) -> 10052288 | I2: =H2*(I3+1) -> 10936889 | J2: =I2*(J3+1) -> 11757155 | K2: =J2*(K3+1) -> 12591914 | N2: =IFERROR((F2/B2)^(1/4)-1,"") -> 0.10609279
A3: % Growth | C3: =C2/B2-1 -> 0.13890076 | D3: =D2/C2-1 -> 0.13135326 | E3: =E2/D2-1 -> 0.049395051 | F3: =F2/E2-1 -> 0.10698854 | G3: 0.117 | H3: 0.085 | I3: 0.088 | J3: 0.075 | K3: 0.071
A4: Cost of sales | B4: -2432839 | C4: -3136483 | D4: -3345821 | E4: -3443831 | F4: -3662148 | G4: =(G2*G5)*-1 -> -4323714.1 | H4: =(H2*H5)*-1 -> -4691229.7 | I4: =(I2*I5)*-1 -> -5104058 | J4: =(J2*J5)*-1 -> -5486862.3 | K4: =(K2*K5)*-1 -> -5876429.5
A5: % of Revenue | B5: =(B4/$C$2)*-1 -> 0.38548879 | C5: =(C4/$C$2)*-1 -> 0.49698275 | D5: =(D4/$D$2)*-1 -> 0.46860061 | E5: =(E4/$E$2)*-1 -> 0.45962428 | F5: =(F4/$F$2)*-1 -> 0.44152358 | G5: =AVERAGE(C5:F5) -> 0.46668281 | H5: 0.46668281 | I5: 0.46668281 | J5: 0.46668281 | K5: 0.46668281
A6: Gross margin | B6: =B2+B4 -> 3108513 | C6: =C2+C4 -> 3174567 | D6: =D2+D4 -> 3794206 | E6: =E2+E4 -> 4048878 | F6: =F2+F4 -> 4632195 | G6: =G2+G4 -> 4941067.1 | H6: =H2+H4 -> 5361057.8 | I6: =I2+I4 -> 5832830.9 | ... K6: =K2+K4 -> 6715484
A7: % of Revenue | C7: =C6/C2 -> 0.50301725 | D7: =D6/D2 -> 0.53139939 | E7: =E6/E2 -> 0.54037572 | F7: =F6/F2 -> 0.55847642 | G7: =G6/G2 -> 0.53331719 | H7: =H6/H2 -> 0.53331719 | I7: =I6/I2 -> 0.53331719 | J7: =J6/J2 -> 0.53331719 | K7: =K6/K2 -> 0.53331719
A9: Freight-Out Costs | B9: -213900 | C9: -249200 | D9: =(223600000/1000)*-1 -> -223600 | E9: -224200 | F9: -237000 | G9: =(G2*G10)*-1 -> -277364.45 | H9: =(H2*H10)*-1 -> -300940.43 | I9: =(I2*I10)*-1 -> -327423.19 | J9: =(J2*J10)*-1 -> -351979.93 | K9: =(K2*K10)*-1 -> -376970.5
A10: % of Revenue | C10: =(C9/$C$2)*-1 -> 0.039486298 | D10: =(D9/$D$2)*-1 -> 0.031316408 | E10: =(E9/$E$2)*-1 -> 0.029922422 | F10: =(F9/$F$2)*-1 -> 0.028573692 | G10: =((AVERAGE(D10:F10))*-1)*-1 -> 0.029937507 | H10: 0.029937507 | I10: 0.029937507 | J10: 0.029937507 | K10: 0.029937507 | N10: 4yr
A11: Advertising and Promotional Expenses | B11: -417600 | C11: -460700 | D11: -528900 | E11: -584100 | F11: -599900 | G11: =(G2*G12)*-1 -> -692874.49 | H11: =(H2*H12)*-1 -> -751768.82 | I11: =(I2*I12)*-1 -> -817924.48 | J11: =(J2*J12)*-1 -> -879268.82 | K11: =(K2*K12)*-1 -> -941696.9 | N11: =IFERROR((F11/B11)^(1/4)-1,"") -> 0.094786902
A12: % of Revenue | B12: =(B11/$C$2)*-1 -> 0.066169655 | C12: =(C11/$C$2)*-1 -> 0.072998946 | D12: =(D11/$D$2)*-1 -> 0.07407535 | E12: =(E11/$E$2)*-1 -> 0.077955783 | F12: =(F11/$F$2)*-1 -> 0.072326404 | G12: =((AVERAGE(D12:F12))*-1)*-1 -> 0.074785846 | H12: 0.074785846 | I12: 0.074785846 | J12: 0.074785846 | K12: 0.074785846
A13: Other expenses | B13: -629391 | C13: -818705 | D13: -1019453 | E13: -1229850 | F13: -1261500 | G13: =(G2*G14)*-1 -> -1417546 | H13: =(H2*H14)*-1 -> -1538037.4 | I13: =(I2*I14)*-1 -> -1673384.7 | J13: =(J2*J14)*-1 -> -1798888.6 | K13: =(K2*K14)*-1 -> -1926609.7
A14: % of Revenue | B14: =(B13/$C$2)*-1 -> 0.099728413 | C14: =(C13/$C$2)*-1 -> 0.12972564 | D14: =(D13/$D$2)*-1 -> 0.14277999 | E14: =(E13/$E$2)*-1 -> 0.16413957 | F14: =(F13/$F$2)*-1 -> 0.15209161 | G14: =((AVERAGE(D14:F14))*-1)*-1 -> 0.15300372 | H14: 0.15300372 | I14: 0.15300372 | J14: 0.15300372 | K14: 0.15300372
A15: Total Operating Costs | B15: =B9+B11+B13 -> -1260891 | C15: =C9+C11+C13 -> -1528605 | D15: =D9+D11+D13 -> -1771953 | E15: =E9+E11+E13 -> -2038150 | F15: =F9+F11+F13 -> -2098400 | G15: =G9+G11+G13 -> -2387785 | H15: =H9+H11+H13 -> -2590746.7 | I15: =I9+I11+I13 -> -2818732.4 | ... K15: =K9+K11+K13 -> -3245277.1
A16: EBITDA | B16: =SUM(B15,B6) -> 1847622 | C16: =SUM(C15,C6) -> 1645962 | D16: =SUM(D15,D6) -> 2022253 | E16: =SUM(E15,E6) -> 2010728 | F16: =SUM(F15,F6) -> 2533795 | G16: =SUM(G15,G6) -> 2553282.1 | H16: =SUM(H15,H6) -> 2770311.1 | I16: =SUM(I15,I6) -> 3014098.5 | ... K16: =SUM(K15,K6) -> 3470206.9
A17: % of Revenue | B17: =((B16/$C$2)*-1)*-1 -> 0.29275984 | C17: =C16/C2 -> 0.26080636 | D17: =D16/D2 -> 0.28322764 | E17: =E16/E2 -> 0.26835795 | F17: =F16/F2 -> 0.30548471 | G17: =G16/G2 -> 0.27559012 | H17: =H16/H2 -> 0.27559012 | I17: =I16/I2 -> 0.27559012 | J17: =J16/J2 -> 0.27559012 | K17: =K16/K2 -> 0.27559012
A19: Depreciation | B19: =(50155)*-1 -> -50155 | C19: =(61241)*-1 -> -61241 | D19: =(68898)*-1 -> -68898 | E19: -80434 | F19: -114441 | G19: =-'Depreciation Schedule'!I19 -> -124400.39 | H19: =-'Depreciation Schedule'!J19 -> -135851.11 | I19: =-'Depreciation Schedule'!K19 -> -148309.49 | J19: =-'Depreciation Schedule'!L19 -> -161702.24 | K19: =-'Depreciation Schedule'!M19 -> -176045.89
A20: Amortization | B20: -4400 | C20: -7600 | D20: -5900 | E20: -7500 | F20: -19300
A21: % of Revenue | B21: =-B19/B2 -> 0.0090510403 | C21: =-C19/C2 -> 0.0097037735 | D21: =-D19/D2 -> 0.0096495433 | E21: =-E19/E2 -> 0.010734969 | F21: =-F19/F2 -> 0.013797476 | G21: =-G19/G2 -> 0.013427235 | H21: =-H19/H2 -> 0.013514447 | I21: =-I19/I2 -> 0.013560482 | ... K21: =-K19/K2 -> 0.013980869
A22: EBIT | B22: =SUM(B16,B19) -> 1797467 | C22: =SUM(C16,C19) -> 1584721 | D22: =SUM(D16,D19) -> 1953355 | E22: =SUM(E16,E19) -> 1930294 | F22: =SUM(F16,F19) -> 2419354 | G22: =SUM(G16,G19) -> 2428881.7 | H22: =SUM(H16,H19) -> 2634460 | I22: =SUM(I16,I19) -> 2865789 | ... K22: =SUM(K16,K19) -> 3294161
A23: % of Revenue | B23: =B22/B2 -> 0.32437337 | C23: =C22/C2 -> 0.25110259 | D23: =D22/D2 -> 0.2735781 | E23: =E22/E2 -> 0.25762298 | F23: =F22/F2 -> 0.29168724 | G23: =G22/G2 -> 0.26216288 | H23: =H22/H2 -> 0.26207567 | I23: =I22/I2 -> 0.26202964 | ... K23: =K22/K2 -> 0.26160925
A25: INTEREST AND OTHER INCOME (EXPENSE), NET | B25: 3952 | C25: -12757 | D25: 115127 | E25: 59165 | F25: 63175 | G25: ='Debt Schedule'!G30-'Debt Schedule'!G28 -> 58532.605 | H25: ='Debt Schedule'!H30-'Debt Schedule'!H28 -> 95172.475 | I25: ='Debt Schedule'!I30-'Debt Schedule'!I28 -> 134991.46 | J25: ='Debt Schedule'!J30-'Debt Schedule'!J28 -> 178596.04 | K25: ='Debt Schedule'!K30-'Debt Schedule'!K28 -> 226054.21
A26: INCOME BEFORE PROVISION FOR INCOME TAXES | B26: =B22+B25 -> 1801419 | C26: =C22+C25 -> 1571964 | D26: =D22+D25 -> 2068482 | E26: =E22+E25 -> 1989459 | F26: =F22+F25 -> 2482529 | G26: =G25+G22 -> 2487414.3 | H26: =H25+H22 -> 2729632.5 | I26: =I25+I22 -> 3000780.5 | J26: =J25+J22 -> 3257049.7 | K26: =K25+K22 -> 3520215.3
A27: % of Revenue | B27: =(B26/$C$2) -> 0.28543887 | C27: =C26/$C$2 -> 0.24908121 | D27: =D26/$D$2 -> 0.28970227 | E27: =E26/$E$2 -> 0.26551932 | F27: =F26/$F$2 -> 0.29930387 | G27: =G26/G2 -> 0.26848064 | H27: =H26/H2 -> 0.27154341 | I27: =I26/I2 -> 0.2743724 | J27: =J26/J2 -> 0.27702701 | K27: =K26/K2 -> 0.27956158
A29: PROVISION FOR INCOME TAXES | B29: -423944 | C29: -380340 | D29: -437494 | E29: -480411 | F29: -577097 | G29: =(G30*G26)*-1 -> -522357.01 | H29: =(H30*H26)*-1 -> -573222.82 | I29: =(I30*I26)*-1 -> -630163.89 | J29: =(J30*J26)*-1 -> -683980.43 | K29: =(K30*K26)*-1 -> -739245.2
A30: Tax Rate | B30: =(B29/$C$2)*-1 -> 0.067174876 | C30: =(C29/C26)*-1 -> 0.24195211 | D30: =(D29/D26)*-1 -> 0.21150486 | E30: =(E29/E26)*-1 -> 0.24147821 | F30: =(F29/F26)*-1 -> 0.23246335 | G30: 0.21 | H30: 0.21 | I30: 0.21 | J30: 0.21 | K30: 0.21
A31: NET INCOME | B31: =SUM(B29,B26) -> 1377475 | C31: =SUM(C29,C26) -> 1191624 | D31: =SUM(D29,D26) -> 1630988 | E31: =SUM(E29,E26) -> 1509048 | F31: =SUM(F29,F26) -> 1905432 | G31: =SUM(G29,G26) -> 1965057.3 | H31: =SUM(H29,H26) -> 2156409.7 | I31: =SUM(I29,I26) -> 2370616.6 | ... K31: =SUM(K29,K26) -> 2780970.1
A32: % of Revenue | B32: =B31/B2 -> 0.24858103 | C32: =C31/C2 -> 0.18881549 | D32: =D31/D2 -> 0.22842883 | E32: =E31/E2 -> 0.20140219 | F32: =F31/F2 -> 0.22972669 | G32: =G31/G2 -> 0.2120997 | H32: =H31/H2 -> 0.2145193 | I32: =I31/I2 -> 0.2167542 | ... K32: =K31/K2 -> 0.22085365
A34: Basic | B34: =B31/B37 -> 1.3025448 | C34: =C31/C37 -> 1.1310474 | D34: =D31/D37 -> 1.5609229 | E34: =E31/E37 -> 1.502189 | F34: =F31/F37 -> 0.97625647 | G34: =G31/G37 -> 1.6074586 | H34: =H31/H37 -> 1.7639888 | I34: =I31/I37 -> 1.9392146 | ... K34: =K31/K37 -> 2.2748925
A35: Diluted | B35: =B31/B38 -> 1.285824 | C35: =C31/C38 -> 1.1173828 | D35: =D31/D38 -> 1.5416042 | E35: =E31/E38 -> 1.4895248 | F35: =F31/F38 -> 0.96776376 | G35: =G31/G38 -> 1.5904415 | H35: =H31/H38 -> 1.7453147 | I35: =I31/I38 -> 1.9186855 | ... K35: =K31/K38 -> 2.2508098
A37: Basic | B37: 1057526 | C37: 1053558 | D37: 1044887 | E37: 1004566 | F37: =975887*2 -> 1951774 | G37: =AVERAGE(B37:F37) -> 1222462.2 | H37: 1222462.2 | I37: 1222462.2 | J37: 1222462.2 | K37: 1222462.2
A38: Diluted | B38: 1071278 | C38: 1066442 | D38: 1057981 | E38: 1013107 | F38: =984451*2 -> 1968902 | G38: =AVERAGE(B38:F38) -> 1235542 | H38: 1235542 | I38: 1235542 | J38: 1235542 | K38: 1235542

Sheet C.S
A1: ($'000) | B1: 2021 | C1: 2022 | D1: 2023 | E1: =D1+1 -> 2024 | F1: =E1+1 -> 2025 | G1: =F1+1 -> 2026 | H1: =G1+1 -> 2027 | I1: =H1+1 -> 2028 | J1: =I1+1 -> 2029 | K1: =J1+1 -> 2030
A2: OPERATING ACTIVITIES
A3: Net income | B3: =I.S!B31 -> 1377475 | C3: =I.S!C31 -> 1191624 | D3: =I.S!D31 -> 1630988 | E3: =I.S!E31 -> 1509048 | F3: =I.S!F31 -> 1905432 | G3: =I.S!G31 -> 1965057.3 | H3: =I.S!H31 -> 2156409.7 | I3: =I.S!I31 -> 2370616.6 | ... K3: =I.S!K31 -> 2780970.1
A4: Depreciation and amortization | B4: 50155 | C4: 61241 | D4: 68898 | E4: 80434 | F4: 114441 | G4: =I.S!G19 -> -124400.39 | H4: =I.S!H19 -> -135851.11 | I4: =I.S!I19 -> -148309.49 | J4: =I.S!J19 -> -161702.24 | K4: =I.S!K19 -> -176045.89
A5: Non-cash lease expense | B5: 4107 | C5: 7337 | D5: 9043 | E5: 13521 | F5: 15398 | G5: =F5*(G6+1) -> 17535.567 | H5: =G5*(H6+1) -> 19969.874 | I5: =H5*(I6+1) -> 22742.114 | J5: =I5*(J6+1) -> 25899.199 | K5: =J5*(K6+1) -> 29494.554
A6: % growth | C6: =C5/B5-1 -> 0.78646214 | D6: =D5/C5-1 -> 0.2325201 | E6: =E5/D5-1 -> 0.49518965 | F6: =F5/E5-1 -> 0.13882109 | G6: =F6 -> 0.13882109 | H6: =G6 -> 0.13882109 | I6: =H6 -> 0.13882109 | J6: =I6 -> 0.13882109 | K6: =J6 -> 0.13882109
A7: Loss (gain) on disposal of property and equipment | B7: -1013 | C7: -185 | D7: 166 | E7: 3328 | F7: 2781 | G7: 3328 | H7: 2781 | I7: 3328 | J7: 2781 | K7: 3328
A8: Gain on Bang Transaction | B8: 0 | C8: 0 | D8: -45382 | E8: — | F8: — | G8: 0 | H8: 0 | I8: 0 | J8: 0 | K8: 0
A9: Loss on impairment of intangibles | B9: 0 | C9: 2200 | D9: 38700 | E9: 127098 | F9: 38411 | G9: =F9 -> 38411 | H9: =G9 -> 38411 | I9: =H9 -> 38411 | J9: =I9 -> 38411 | K9: =J9 -> 38411
A10: Loss on impairment of property and equipment | B10: 0 | C10: 0 | D10: 4336 | E10: 8184 | F10: 12029 | G10: =F10 -> 12029 | H10: =G10 -> 12029 | I10: =H10 -> 12029 | J10: =I10 -> 12029 | K10: =J10 -> 12029
A11: Stock-based compensation | B11: 70483 | C11: 64108 | D11: 68836 | E11: 90985 | F11: 125687 | G11: =(G12*I.S!G15)*-1 -> 115197.89 | H11: =(H12*I.S!H15)*-1 -> 124989.72 | I11: =(I12*I.S!I15)*-1 -> 135988.82 | J11: =(J12*I.S!J15)*-1 -> 146187.98 | K11: =(K12*I.S!K15)*-1 -> 156567.33
A12: % of operating expenses | B12: =B11/-I.S!B15 -> 0.05589936 | C12: =C11/-I.S!C15 -> 0.041938892 | D12: =D11/-I.S!D15 -> 0.038847532 | E12: =E11/-I.S!E15 -> 0.044640973 | F12: =F11/-I.S!F15 -> 0.059896588 | G12: =AVERAGE(B12:F12) -> 0.048244669 | H12: 0.048244672 | I12: 0.048244672 | J12: 0.048244672 | K12: 0.048244672
A13: Deferred income taxes | B13: 16429 | C13: 48182 | D13: 2040 | E13: -11705 | F13: 4210 | G13: ='Depreciation Schedule'!I40 -> 8174.8903 | H13: ='Depreciation Schedule'!J40 -> 8553.4574 | I13: ='Depreciation Schedule'!K40 -> 4278.105 | J13: ='Depreciation Schedule'!L40 -> 530.2208 | K13: ='Depreciation Schedule'!M40 -> -483.59694
A14: Other liabilities (moved from operating assets) | B14: 492 | C14: -4540 | D14: 22951 | E14: 13390 | F14: -4935 | G14: 13390 | H14: -4935 | I14: 13390 | J14: -4935 | K14: 13390
A15: Changes in operating assets and liabilities:
A16: Accounts receivable | B16: -254228 | C16: -128981 | D16: -163158 | E16: -93915 | F16: -300600 | G16: =('Working Capital Schedule'!G4-'Working Capital Schedule'!F4)*-1 -> 113612.34 | H16: =('Working Capital Schedule'!H4-'Working Capital Schedule'!G4)*-1 -> -127879.07 | I16: =('Working Capital Schedule'!I4-'Working Capital Schedule'!H4)*-1 -> -143645.81 | J16: =('Working Capital Schedule'!J4-'Working Capital Schedule'!I4)*-1 -> -133198.84 | K16: =('Working Capital Schedule'!K4-'Working Capital Schedule'!J4)*-1 -> -135552.02
A17: Inventories | B17: -277793 | C17: -347712 | D17: 7898 | E17: 211503 | F17: -34918 | G17: =('Working Capital Schedule'!G6-'Working Capital Schedule'!F6)*-1 -> -107546.93 | H17: =('Working Capital Schedule'!H6-'Working Capital Schedule'!G6)*-1 -> -77109.444 | I17: =('Working Capital Schedule'!I6-'Working Capital Schedule'!H6)*-1 -> -86616.585 | J17: =('Working Capital Schedule'!J6-'Working Capital Schedule'!I6)*-1 -> -80317.197 | K17: =('Working Capital Schedule'!K6-'Working Capital Schedule'!J6)*-1 -> -81736.134
A18: Prepaid expenses and other assets | B18: -29341 | C18: -38268 | D18: -10215 | E18: 8959 | F18: -39307 | G18: =('Working Capital Schedule'!G8-'Working Capital Schedule'!F8)*-1 -> -16391.84 | H18: =('Working Capital Schedule'!H8-'Working Capital Schedule'!G8)*-1 -> -10195.148 | I18: =('Working Capital Schedule'!I8-'Working Capital Schedule'!H8)*-1 -> -11452.143 | J18: =('Working Capital Schedule'!J8-'Working Capital Schedule'!I8)*-1 -> -10619.26 | K18: =('Working Capital Schedule'!K8-'Working Capital Schedule'!J8)*-1 -> -10806.867
A19: Prepaid income taxes | B19: -10919 | C19: -4439 | D19: -18833 | E19: 3062 | F19: -21094 | G19: =('Working Capital Schedule'!G10-'Working Capital Schedule'!F10)*-1 -> 22051.066 | H19: =('Working Capital Schedule'!H10-'Working Capital Schedule'!G10)*-1 -> -5120.6856 | I19: =('Working Capital Schedule'!I10-'Working Capital Schedule'!H10)*-1 -> -5732.2857 | J19: =('Working Capital Schedule'!J10-'Working Capital Schedule'!I10)*-1 -> -5417.7366 | K19: =('Working Capital Schedule'!K10-'Working Capital Schedule'!J10)*-1 -> -5563.5318
A20: Accounts payable | B20: 114297 | C20: 49765 | D20: 112786 | E20: -61491 | F20: 78460 | G20: ='Working Capital Schedule'!G14-'Working Capital Schedule'!F14 -> 43683.415 | H20: ='Working Capital Schedule'!H14-'Working Capital Schedule'!G14 -> 51820.88 | I20: ='Working Capital Schedule'!I14-'Working Capital Schedule'!H14 -> 58210.09 | J20: ='Working Capital Schedule'!J14-'Working Capital Schedule'!I14 -> 53976.629 | K20: ='Working Capital Schedule'!K14-'Working Capital Schedule'!J14 -> 54930.216
A21: Accrued liabilities | B21: 71586 | C21: -30419 | D21: -10393 | E21: 18371 | F21: 81341 | G21: ='Working Capital Schedule'!G16-'Working Capital Schedule'!F16 -> -46962.392 | H21: ='Working Capital Schedule'!H16-'Working Capital Schedule'!G16 -> 22025.437 | I21: ='Working Capital Schedule'!I16-'Working Capital Schedule'!H16 -> 24741.028 | J21: ='Working Capital Schedule'!J16-'Working Capital Schedule'!I16 -> 22941.68 | K21: ='Working Capital Schedule'!K16-'Working Capital Schedule'!J16 -> 23346.983
A22: Accrued promotional allowances | B22: 31498 | C22: 50821 | D22: 8418 | E22: 9736 | F22: 98266 | G22: ='Working Capital Schedule'!G18-'Working Capital Schedule'!F18 -> -37809.203 | H22: ='Working Capital Schedule'!H18-'Working Capital Schedule'!G18 -> 29432.188 | I22: ='Working Capital Schedule'!I18-'Working Capital Schedule'!H18 -> 33060.983 | J22: ='Working Capital Schedule'!J18-'Working Capital Schedule'!I18 -> 30656.548 | K22: ='Working Capital Schedule'!K18-'Working Capital Schedule'!J18 -> 31198.147
A23: Accrued compensation | B23: 7950 | C23: 3729 | D23: 13398 | E23: 5947 | F23: 17801 | G23: ='Working Capital Schedule'!G20-'Working Capital Schedule'!F20 -> 8229.6162 | H23: ='Working Capital Schedule'!H20-'Working Capital Schedule'!G20 -> 4551.9755 | I23: ='Working Capital Schedule'!I20-'Working Capital Schedule'!H20 -> 5113.2041 | J23: ='Working Capital Schedule'!J20-'Working Capital Schedule'!I20 -> 4741.3347 | K23: ='Working Capital Schedule'!K20-'Working Capital Schedule'!J20 -> 4825.0983
A24: Income taxes payable | B24: 7221 | C24: -16860 | D24: 1748 | E24: 9438 | F24: 27779 | G24: ='Working Capital Schedule'!G22-'Working Capital Schedule'!F22 -> -18472.402 | H24: ='Working Capital Schedule'!H22-'Working Capital Schedule'!G22 -> 9304.4762 | I24: ='Working Capital Schedule'!I22-'Working Capital Schedule'!H22 -> 10415.776 | J24: ='Working Capital Schedule'!J22-'Working Capital Schedule'!I22 -> 9844.229 | K24: ='Working Capital Schedule'!K22-'Working Capital Schedule'!J22 -> 10109.144
A25: Deferred revenue | B25: -22658 | C25: -19905 | D25: -24472 | E25: -17360 | F25: -23005 | G25: ='Working Capital Schedule'!G24-'Working Capital Schedule'!F24 -> -15523.323 | H25: ='Working Capital Schedule'!H24-'Working Capital Schedule'!G24 -> 1426.4425 | I25: ='Working Capital Schedule'!I24-'Working Capital Schedule'!H24 -> 1602.3145 | J25: ='Working Capital Schedule'!J24-'Working Capital Schedule'!I24 -> 1485.7825 | K25: ='Working Capital Schedule'!K24-'Working Capital Schedule'!J24 -> 1512.0314
A26: Net working capital | B26: =SUM(B16:B25) -> -362387 | C26: =SUM(C16:C25) -> -482269 | D26: =SUM(D16:D25) -> -82823 | E26: =SUM(E16:E25) -> 94250 | F26: =SUM(F16:F25) -> -115277 | G26: =SUM(G16:G25) -> -55129.652 | H26: =SUM(H16:H25) -> -101742.95 | I26: =SUM(I16:I25) -> -114303.43 | ... K26: =SUM(K16:K25) -> -107736.93
A27: Cash from operations before changes in working capital | B27: =SUM(B3:B25) -> 1155741.1 | C27: =SUM(C3:C25) -> 887698.83 | D27: =SUM(D3:D25) -> 1717753.3 | E27: =SUM(E3:E25) -> 1928533.5 | F27: =SUM(F3:F25) -> 2098177.2 | G27: =G3+G4+G5+G7+G8+G9+G10+G11+G13+G14+G16+G17+G18+G19+G20+G21+G22+G23+G24+G25 -> 1993593.6 | H27: =H3+H4+H5+H7+H8+H9+H10+H11+H13+H14+H16+H17+H18+H19+H20+H21+H22+H23+H24+H25 -> 2120614.7 | I27: =I3+I4+I5+I7+I8+I9+I10+I11+I13+I14+I16+I17+I18+I19+I20+I21+I22+I23+I24+I25 -> 2338170.7 | J27: =J3+J4+J5+J7+J8+J9+J10+J11+J13+J14+J16+J17+J18+J19+J20+J21+J22+J23+J24+J25 -> 2526363.6 | K27: =K3+K4+K5+K7+K8+K9+K10+K11+K13+K14+K16+K17+K18+K19+K20+K21+K22+K23+K24+K25 -> 2749923.5
A30: INVESTING ACTIVITIES
A31: Sales of available-for-sale investments + Purchases of available-for-sale investments (combine) | B31: -924544 | C31: -358468 | D31: -132119 | E31: 1146478 | F31: 219655 | G31: =D31 -> -132119 | H31: -132119 | I31: -132119 | J31: -132119 | K31: -132119
A32: Acquisition of Bang Energy | B32: 0 | C32: 0 | D32: -363385 | E32: 0 | F32: 0 | G32: 0 | H32: 0 | I32: 0 | J32: 0 | K32: 0
A33: Acquisition of CANarchy, net of cash | B33: 0 | C33: -329472 | D33: 0 | G33: 0 | H33: 0 | I33: 0 | J33: 0 | K33: 0
A34: Purchases of property and equipment | B34: -43868 | C34: -188726 | D34: -221428 | E34: -264074 | F34: -132275 | G34: =-G35*I.S!G2 -> -147751.17 | H34: =-H35*I.S!H2 -> -160310.02 | I34: =-I35*I.S!I2 -> -174417.31 | J34: =-J35*I.S!J2 -> -187498.61 | K34: =-K35*I.S!K2 -> -200811.01
A35: % of Revenue | B35: =B34/-I.S!B2 -> 0.0079164796 | C35: =C34/-I.S!C2 -> 0.029904057 | D35: =D34/-I.S!D2 -> 0.031012208 | E35: =E34/-I.S!E2 -> 0.035244129 | F35: =F34/-I.S!F2 -> 0.015947616 | G35: =F35 -> 0.015947616 | H35: 0.015947616 | I35: 0.015947616 | J35: 0.015947616 | K35: 0.015947616
A36: Proceeds from sale of property and equipment | B36: 1328 | C36: 1313 | D36: 2520 | E36: 2732 | F36: 4299 | G36: 0 | H36: 0 | I36: 0 | J36: 0 | K36: 0
A37: Additions to intangibles | B37: -13585 | C37: -23427 | D37: -13296 | E37: -42360 | F37: -25254 | G37: 0 | H37: 0 | I37: 0 | J37: 0 | K37: 0
A38: Increase in other assets | B38: -11353 | C38: -26343 | D38: -6825 | E38: 1635 | F38: -398 | G38: 0 | H38: 0 | I38: 0 | J38: 0 | K38: 0
A39: Net cash used in investing activities | B39: =SUM(B31:B38) -> -992021.99 | C39: =SUM(C31:C38) -> -925122.97 | D39: =SUM(D31:D38) -> -734532.97 | E39: =SUM(E31:E38) -> 844411.04 | F39: =SUM(F31:F38) -> 66027.016 | G39: =G31+G32+G33+G34+G36+G37+G38 -> -279870.17 | H39: =H31+H32+H33+H34+H36+H37+H38 -> -292429.02 | I39: =I31+I32+I33+I34+I36+I37+I38 -> -306536.31 | J39: =J31+J32+J33+J34+J36+J37+J38 -> -319617.61 | K39: =K31+K32+K33+K34+K36+K37+K38 -> -332930.01
A41: FINANCING ACTIVITIES
A42: Payments on short-term debt | B42: 2928 | C42: 75 | D42: -13914 | E42: -8223 | F42: -10344 | G42: ='Debt Schedule'!G13+'Debt Schedule'!G14 -> 0 | H42: ='Debt Schedule'!H13+'Debt Schedule'!H14 -> 0 | I42: ='Debt Schedule'!I13+'Debt Schedule'!I14 -> 0 | J42: ='Debt Schedule'!J13+'Debt Schedule'!J14 -> 0 | K42: ='Debt Schedule'!K13+'Debt Schedule'!K14 -> 0
A43: Borrowings + Payments on credit facilities (combined) | B43: 45723 | C43: 45723 | D43: 45723 | E43: -329277 | F43: -329277 | G43: ='Debt Schedule'!G21+'Debt Schedule'!G22 -> 0 | H43: ='Debt Schedule'!H21+'Debt Schedule'!H22 -> 0 | I43: ='Debt Schedule'!I21+'Debt Schedule'!I22 -> 0 | J43: ='Debt Schedule'!J21+'Debt Schedule'!J22 -> 0 | K43: ='Debt Schedule'!K21+'Debt Schedule'!K22 -> 0
...

Sheet B.S
A1: ($'000) | B1: 2022 | C1: 2023 | D1: =C1+1 -> 2024 | E1: =D1+1 -> 2025 | F1: =E1+1 -> 2026 | G1: =F1+1 -> 2027 | H1: =G1+1 -> 2028 | I1: =H1+1 -> 2029 | J1: =I1+1 -> 2030
A2: Assets
A3: Cash and cash equivalents | B3: 1307141 | C3: 2297675 | D3: 1533287 | E3: 2088117 | F3: =E3+'C.S'!G50 -> 3765143.5 | G3: =F3+'C.S'!H50 -> 5752104.1 | H3: =G3+'C.S'!I50 -> 7747041.5 | I3: =H3+'C.S'!J50 -> 10112562 | J3: =I3+'C.S'!K50 -> 12492859
A4: Short-term investments | B4: 1362314 | C4: 955605 | D4: 0 | E4: 677084 | F4: =E4-'C.S'!G31 -> 809203 | G4: =F4-'C.S'!H31 -> 941322 | H4: =G4-'C.S'!I31 -> 1073441 | I4: =H4-'C.S'!J31 -> 1205560 | J4: =I4-'C.S'!K31 -> 1337679
A5: Accounts receivable, net | B5: 1016203 | C5: 1193964 | D5: 1221646 | E5: 1618072 | F5: =E5-'C.S'!G16 -> 1504459.7 | G5: =F5-'C.S'!H16 -> 1632338.7 | H5: =G5-'C.S'!I16 -> 1775984.5 | I5: =H5-'C.S'!J16 -> 1909183.4 | J5: =I5-'C.S'!K16 -> 2044735.4
A6: Inventories | B6: 935631 | C6: 971406 | D6: 737107 | E6: 799623 | F6: =E6-'C.S'!G17 -> 907169.93 | G6: =F6-'C.S'!H17 -> 984279.37 | H6: =G6-'C.S'!I17 -> 1070896 | I6: =H6-'C.S'!J17 -> 1151213.2 | J6: =I6-'C.S'!K17 -> 1232949.3
A7: Prepaid expenses and other current assets | B7: 109823 | C7: 116195 | D7: 107262 | E7: 103551 | F7: =E7-'C.S'!G18 -> 119942.84 | G7: =F7-'C.S'!H18 -> 130137.99 | H7: =G7-'C.S'!I18 -> 141590.13 | I7: =H7-'C.S'!J18 -> 152209.39 | J7: =I7-'C.S'!K18 -> 163016.26
A8: Prepaid income taxes | B8: 33785 | C8: 54151 | D8: 42202 | E8: 74637 | F8: =E8-'C.S'!G19 -> 52585.934 | G8: =F8-'C.S'!H19 -> 57706.619 | H8: =G8-'C.S'!I19 -> 63438.905 | I8: =H8-'C.S'!J19 -> 68856.642 | J8: =I8-'C.S'!K19 -> 74420.173
A9: Total current assets | B9: =SUM(B3:B8) -> 4764897 | C9: =SUM(C3:C8) -> 5588996 | D9: =SUM(D3:D8) -> 3641504 | E9: =SUM(E3:E8) -> 5361084 | F9: =SUM(F3:F8) -> 7158504.8 | G9: =SUM(G3:G8) -> 9497888.8 | H9: =SUM(H3:H8) -> 11872392 | I9: =SUM(I3:I8) -> 14599585 | J9: =SUM(J3:J8) -> 17345659
A11: Long-Term Assets
A12: INVESTMENTS | B12: 61443 | C12: 76431 | D12: 0 | E12: 487329 | F12: =E12 -> 487329 | G12: =F12 -> 487329 | H12: =G12 -> 487329 | I12: =H12 -> 487329 | J12: =I12 -> 487329
A13: PROPERTY AND EQUIPMENT, net | B13: 516897 | C13: 890796 | D13: 1047024 | E13: 1081544 | F13: =E13-'C.S'!G34-'C.S'!G4-'C.S'!G7-'C.S'!G10-'C.S'!G32-'C.S'!G33-'C.S'!G36-'C.S'!G8 -> 1338338.6 | G13: =F13-'C.S'!H34-'C.S'!H4-'C.S'!H7-'C.S'!H10-'C.S'!H32-'C.S'!H33-'C.S'!H36-'C.S'!H8 -> 1619689.7 | H13: =G13-'C.S'!I34-'C.S'!I4-'C.S'!I7-'C.S'!I10-'C.S'!I32-'C.S'!I33-'C.S'!I36-'C.S'!I8 -> 1927059.5 | I13: =H13-'C.S'!J34-'C.S'!J4-'C.S'!J7-'C.S'!J10-'C.S'!J32-'C.S'!J33-'C.S'!J36-'C.S'!J8 -> 2261450.3 | J13: =I13-'C.S'!K34-'C.S'!K4-'C.S'!K7-'C.S'!K10-'C.S'!K32-'C.S'!K33-'C.S'!K36-'C.S'!K8 -> 2622950.2
A14: DEFERRED INCOME TAXES, net | B14: 177039 | C14: 175003 | D14: 184260 | E14: 188646 | F14: =E14-'C.S'!G13 -> 180471.11 | G14: =F14-'C.S'!H13 -> 171917.65 | H14: =G14-'C.S'!I13 -> 167639.55 | I14: =H14-'C.S'!J13 -> 167109.33 | J14: =I14-'C.S'!K13 -> 167592.92
A15: GOODWILL | B15: 1417941 | C15: 1417941 | D15: 1331643 | E15: 1331643 | F15: =E15 -> 1331643 | G15: =F15 -> 1331643 | H15: =G15 -> 1331643 | I15: =H15 -> 1331643 | J15: =I15 -> 1331643
A16: OTHER INTANGIBLE ASSETS, net | B16: 1220410 | C16: 1427139 | D16: 1414252 | E16: 1379268 | F16: =E16-'C.S'!G37-'C.S'!G9 -> 1340857 | G16: =F16-'C.S'!H37-'C.S'!H9 -> 1302446 | H16: =G16-'C.S'!I37-'C.S'!I9 -> 1264035 | I16: =H16-'C.S'!J37-'C.S'!J9 -> 1225624 | J16: =I16-'C.S'!K37-'C.S'!K9 -> 1187213
A17: OTHER ASSETS | B17: 134478 | C17: 110216 | D17: 100406 | E17: 159431 | F17: =E17 -> 159431 | G17: =F17 -> 159431 | H17: =G17 -> 159431 | I17: =H17 -> 159431 | J17: =I17 -> 159431
A18: Total Long Term Assets | B18: =SUM(B12:B17) -> 3528208 | C18: =SUM(C12:C17) -> 4097526 | D18: =SUM(D12:D17) -> 4077585 | E18: =SUM(E12:E17) -> 4627861 | F18: =SUM(F12:F17) -> 4838069.7 | G18: =SUM(G12:G17) -> 5072456.4 | H18: =SUM(H12:H17) -> 5337137 | I18: =SUM(I12:I17) -> 5632586.7 | J18: =SUM(J12:J17) -> 5956159.2
A19: Total Assets | B19: =B18+B9 -> 8293105 | C19: =C18+C9 -> 9686522 | D19: =D18+D9 -> 7719089 | E19: =E18+E9 -> 9988945 | F19: =F18+F9 -> 11996574 | G19: =G18+G9 -> 14570345 | H19: =H18+H9 -> 17209529 | I19: =I18+I9 -> 20232172 | J19: =J18+J9 -> 23301818
A23: Current Liabilities
A24: Accounts payable | B24: 444265 | C24: 564379 | D24: 466775 | E24: 565974 | F24: =E24+'C.S'!G20 -> 609657.41 | G24: =F24+'C.S'!H20 -> 661478.29 | H24: =G24+'C.S'!I20 -> 719688.38 | I24: =H24+'C.S'!J20 -> 773665.01 | J24: =I24+'C.S'!K20 -> 828595.23
A25: Accrued liabilities | B25: 172991 | C25: 183988 | D25: 220764 | E25: 306085 | F25: =E25+'C.S'!G21 -> 259122.61 | G25: =F25+'C.S'!H21 -> 281148.05 | H25: =G25+'C.S'!I21 -> 305889.07 | I25: =H25+'C.S'!J21 -> 328830.75 | J25: =I25+'C.S'!K21 -> 352177.74
A26: Accrued promotional allowances | B26: 255631 | C26: 269061 | D26: 267711 | E26: 384070 | F26: =E26+'C.S'!G22 -> 346260.8 | G26: =F26+'C.S'!H22 -> 375692.98 | H26: =G26+'C.S'!I22 -> 408753.97 | I26: =H26+'C.S'!J22 -> 439410.52 | J26: =I26+'C.S'!K22 -> 470608.66
A27: Deferred revenue | B27: 43311 | C27: 41914 | D27: 45809 | E27: 45323 | F27: =E27+'C.S'!G25 -> 29799.677 | G27: =F27+'C.S'!H25 -> 31226.119 | H27: =G27+'C.S'!I25 -> 32828.434 | I27: =H27+'C.S'!J25 -> 34314.216 | J27: =I27+'C.S'!K25 -> 35826.248
A28: Accrued compensation | B28: 72463 | C28: 87392 | D28: 92454 | E28: 114023 | F28: =E28+'C.S'!G23 -> 122252.62 | G28: =F28+'C.S'!H23 -> 126804.59 | H28: =G28+'C.S'!I23 -> 131917.8 | I28: =H28+'C.S'!J23 -> 136659.13 | J28: =I28+'C.S'!K23 -> 141484.23
A29: Income taxes payable | B29: 13317 | C29: 14955 | D29: 4006 | E29: 32305 | F29: =E29+'C.S'!G24 -> 13832.598 | G29: =F29+'C.S'!H24 -> 23137.074 | H29: =G29+'C.S'!I24 -> 33552.85 | I29: =H29+'C.S'!J24 -> 43397.079 | J29: =I29+'C.S'!K24 -> 53506.223
A30: Payments on short term debt | B30: 0 | C30: 0 | D30: 0 | E30: 0 | F30: =E30+'C.S'!G42 -> 0 | G30: =F30+'C.S'!H42 -> 0 | H30: =G30+'C.S'!I42 -> 0 | I30: =H30+'C.S'!J42 -> 0 | J30: =I30+'C.S'!K42 -> 0
A31: Current liabilities | B31: =SUM(B24:B29) -> 1001978 | C31: =SUM(C24:C29) -> 1161689 | D31: =SUM(D24:D29) -> 1097519 | E31: =SUM(E24:E29) -> 1447780 | F31: =SUM(F24:F29) -> 1380925.7 | G31: =SUM(G24:G29) -> 1499487.1 | H31: =SUM(H24:H29) -> 1632630.5 | I31: =SUM(I24:I29) -> 1756276.7 | J31: =SUM(J24:J29) -> 1882198.3
A34: Long-Term Liabilities
A35: Deferred revenue | B35: 223800 | C35: 204251 | D35: 179008 | E35: 159991 | F35: =E35 -> 159991 | G35: =F35 -> 159991 | H35: =G35 -> 159991 | I35: =H35 -> 159991 | J35: =I35 -> 159991
A36: OTHER LIABILITIES | B36: 42286 | C36: 91838 | D36: 110893 | E36: 127066 | F36: =E36+'C.S'!G5+'C.S'!G14 -> 157991.57 | G36: =F36+'C.S'!H43+'C.S'!H5+'C.S'!H14 -> 173026.44 | H36: =G36+'C.S'!I43+'C.S'!I5+'C.S'!I14 -> 209158.55 | I36: =H36+'C.S'!J43+'C.S'!J5+'C.S'!J14 -> 230122.75 | J36: =I36+'C.S'!K43+'C.S'!K5+'C.S'!K14 -> 273007.31
A37: LONG-TERM DEBT | D37: 373951 | E37: 0 | F37: =E37+'C.S'!G43+'C.S'!G44 -> 0 | G37: =F37+'C.S'!H44 -> 0 | H37: =G37+'C.S'!I44 -> 0 | I37: =H37+'C.S'!J44 -> 0 | J37: =I37+'C.S'!K44 -> 0
A38: Non‑current liabilities | B38: =SUM(B35:B36) -> 266086 | C38: =SUM(C35:C36) -> 296089 | D38: =SUM(D35:D36) -> 289901 | E38: =SUM(E35:E36) -> 287057 | F38: =SUM(F35:F36) -> 317982.57 | G38: =SUM(G35:G36) -> 333017.44 | H38: =SUM(H35:H36) -> 369149.55 | I38: =SUM(I35:I36) -> 390113.75 | J38: =SUM(J35:J36) -> 432998.31
A39: Total Liabilities | B39: =B38+B31 -> 1268064 | C39: =C38+C31 -> 1457778 | D39: =D38+D31 -> 1387420 | E39: =E38+E31 -> 1734837 | F39: =F38+F31 -> 1698908.3 | G39: =G38+G31 -> 1832504.6 | H39: =H38+H31 -> 2001780.1 | I39: =I38+I31 -> 2146390.5 | J39: =J38+J31 -> 2315196.6
A41: Liabilities and equity
A42: Common Stock | B42: 6418 | C42: 5613 | D42: 5632 | E42: 5665 | F42: =E42+'C.S'!G45+'C.S'!G11 -> 285430.89 | G42: =F42+'C.S'!H45+'C.S'!H11 -> 574988.62 | H42: =G42+'C.S'!I45+'C.S'!I11 -> 875545.44 | I42: =H42+'C.S'!J45+'C.S'!J11 -> 1186301.4 | J42: =I42+'C.S'!K45+'C.S'!K11 -> 1507436.7
A43: Additional paid-in capital | B43: 4776804 | C43: 4975115 | D43: 5144922 | E43: 5430847 | F43: =E43+'C.S'!G46 -> 5327201 | G43: =F43+'C.S'!H46 -> 5223555 | H43: =G43+'C.S'!I46 -> 5119909 | I43: =H43+'C.S'!J46 -> 5016263 | J43: =I43+'C.S'!K46 -> 4912617
A44: Retained earnings | B44: 9001173 | C44: 5939736 | D44: 7448784 | E44: 9354216 | F44: =E44+'C.S'!G3 -> 11319273 | G44: =F44+'C.S'!H3 -> 13475683 | H44: =G44+'C.S'!I3 -> 15846300 | I44: =H44+'C.S'!J3 -> 18419369 | J44: =I44+'C.S'!K3 -> 21200339
A45: Accumulated other comprehensive loss | B45: -159073 | C45: -125337 | D45: -269487 | E45: -60841 | F45: =E45+'C.S'!G49 -> -158460 | G45: =F45+'C.S'!H49 -> -60607 | H45: =G45+'C.S'!I49 -> -158226 | I45: =H45+'C.S'!J49 -> -60373 | J45: =I45+'C.S'!K49 -> -157992
A47: Common Stock in Treasury | B47: -6600281 | C47: -2566383 | D47: -6372133 | E47: -6475779 | F47: =E47 -> -6475779 | G47: =F47 -> -6475779 | H47: =G47 -> -6475779 | I47: =H47 -> -6475779 | J47: =I47 -> -6475779
A48: Total stockholders’ equity | B48: =SUM(B42:B47) -> 7025041 | C48: =SUM(C42:C47) -> 8228744 | D48: =SUM(D42:D47) -> 5957718 | E48: =SUM(E42:E47) -> 8254108 | F48: =SUM(F42:F47) -> 10297666 | G48: =SUM(G42:G47) -> 12737841 | H48: =SUM(H42:H47) -> 15207749 | I48: =SUM(I42:I47) -> 18085781 | J48: =SUM(J42:J47) -> 20986622
...

Sheet >>Valuation
A2: ($'000) | B2: 2021 | C2: 2022 | D2: 2023 | E2: =D2+1 -> 2024 | F2: =E2+1 -> 2025 | G2: =F2+1 -> 2026 | H2: =G2+1 -> 2027 | I2: =H2+1 -> 2028
A4: Unlevered Free Cash Flow
A5: EBIT | E5: =I.S!G22 -> 2428881.7 | F5: =I.S!H22 -> 2634460 | G5: =I.S!I22 -> 2865789 | H5: =I.S!J22 -> 3078453.6 | I5: =I.S!K22 -> 3294161
A6: Depreciation & Amortization | E6: ='C.S'!G4 -> -124400.39 | F6: ='C.S'!H4 -> -135851.11 | G6: ='C.S'!I4 -> -148309.49 | H6: ='C.S'!J4 -> -161702.24 | I6: ='C.S'!K4 -> -176045.89
A7: Changes in Capital | E7: ='C.S'!G26 -> -55129.652 | F7: ='C.S'!H26 -> -101742.95 | G7: ='C.S'!I26 -> -114303.43 | H7: ='C.S'!J26 -> -105906.83 | I7: ='C.S'!K26 -> -107736.93
A8: Capital Expenditure | E8: ='C.S'!G34 -> -147751.17 | F8: ='C.S'!H34 -> -160310.02 | G8: ='C.S'!I34 -> -174417.31 | H8: ='C.S'!J34 -> -187498.61 | I8: ='C.S'!K34 -> -200811.01
A9: Taxes | E9: =-(I.S!G30*'>>Valuation'!E5) -> -510065.16 | F9: =-(I.S!H30*'>>Valuation'!F5) -> -553236.6 | G9: =-(I.S!I30*'>>Valuation'!G5) -> -601815.69 | H9: =-(I.S!J30*'>>Valuation'!H5) -> -646475.26 | I9: =-(I.S!K30*'>>Valuation'!I5) -> -691773.82
A10: Total Unlevered Free Cash Flow | E10: =SUM(E5:E9) -> 1591535.4 | F10: =SUM(F5:F9) -> 1683319.3 | G10: =SUM(G5:G9) -> 1826943.1 | H10: =SUM(H5:H9) -> 1976870.7 | I10: =SUM(I5:I9) -> 2117793.4
A12: Net Present Value Calculation
A13: Period | E13: 1 | F13: 2 | G13: 3 | H13: 4 | I13: 5
A14: Discounted Cash Flow | D14: =J25 -> 0.07148374 | E14: =E10/(1+$D$14)^E13 -> 1485356.5 | F14: =F10/(1+$D$14)^F13 -> 1466207.2 | G14: =G10/(1+$D$14)^G13 -> 1485143 | H14: =H10/(1+$D$14)^H13 -> 1499808.9 | I14: =I10/(1+$D$14)^I13 -> 1499531.8
A15: Total Net Present Value | D15: =SUM(E14:I14) -> 7436047.3
A17: Terminal Value
A18: EBITDA Method | H18: Cost of Capital
A19: Exit Year EBITDA | C19: =I5+I6 -> 3118115.2 | H19: Risk Free Rate | J19: 0.0479 | K19: Debt YE 2019 | M19: =B.S!E30+B.S!E36+B.S!E37 -> 127066
A20: Multiple | C20: =(M22+M23)/I.S!K16 -> 25.919865 | H20: Market Risk Premium | J20: 0.0446 | K20: Stock Price | M20: 46.68
A21: Terminal Value | C21: =C20*C19 -> 80821123 | H21: Beta | J21: 0.53 | K21: Shares Outstanding | M21: =I.S!F38 -> 1968902
A22: Net Present Value | C22: =C21/(1+D14)^I13 -> 57226470 | H22: Cost of Equity | J22: =J19+(J21*J20) -> 0.071538 | K22: Equity Value | M22: =M21*M20 -> 91908345
A23: Perpetuity Method | H23: Cost of Debt | J23: 0.042 | K23: Net Debt | M23: ='>>Valuation'!M19-B.S!E3 -> -1961051
A24: Unlevered Free Cash Flow | C24: =I10 -> 2117793.4
A25: Growth Rate | C25: 0.03 | H25: WACC | J25: =((M22/(M22+M19))*J22)+(M19/(M22+M19)*(J23*(1-I.S!F30))) -> 0.07148374 | K25: Enterprise Value | M25: =M22+M23 -> 89947294
A26: Terminal Value | C26: =C24*(1+C25)/(D14-C25) -> 52582704
A27: Net Present Value | C27: =C26/(1+D14)^I13 -> 37231882
A29: Discounted Cash Flow Total Valuable | B29: EBITDA Method | C29: Perpetuity Method
A30: Total of Present Value of Cash Flows | B30: =D15 -> 7436047.3 | C30: =D15 -> 7436047.3
A31: Present Value of Terminal Value | B31: =C22 -> 57226470 | C31: =C27 -> 37231882
A32: Total Enterprise Value | B32: =SUM(B30:B31) -> 64662517 | C32: =SUM(C30:D31) -> 44667930
A33: Net Debt Non-controlling interests, preferred securities | B33: =M23 -> -1961051 | C33: =B33 -> -1961051
A34: Equity Value | B34: =B32-B33 -> 66623568 | C34: =C32-C33 -> 46628981
A35: Share Count (millions) | B35: =M21 -> 1968902 | C35: =B35 -> 1968902
A36: Estimated Equity Value per Share | B36: =B34/B35 -> 33.83793 | C36: =C34/C35 -> 23.682733
E39: EBITDA Equity Value
B40: =B36 -> 33.83793 | C40: =D40-1 -> 24 | D40: =E40-1 -> 25 | E40: 26 | F40: =E40+1 -> 27 | G40: =F40+1 -> 28
B41: =B42-1% -> 0.0515 | C41: 34.563003 | D41: 35.795034 | E41: 37.027065 | F41: 38.259096 | G41: 39.491127
B42: =B43-1% -> 0.0615 | C42: 33.082935 | D42: 34.258017 | E42: 35.433099 | F42: 36.60818 | G42: 37.783262
B43: 0.0715 | C43: 31.682881 | D43: 32.804143 | E43: 33.925405 | F43: 35.046667 | G43: 36.167929
B44: =B43+1% -> 0.0815 | C44: 30.357798 | D44: 31.428172 | E44: 32.498545 | F44: 33.568919 | G44: 34.639293
B45: =B44+1% -> 0.0915 | C45: 29.103007 | D45: 30.125239 | E45: 31.147471 | F45: 32.169702 | G45: 33.191934
E48: Perpetuity Equity Value
B49: =C36 -> 23.682733 | C49: =D49-0.5% -> 0.02 | D49: =E49-0.5% -> 0.025 | E49: 0.03 | F49: =E49+0.5% -> 0.035 | G49: =F49+0.5% -> 0.04
...

Sheet Working Capital Schedule
A1: Operating Working Capital
A3: DCF (30/09/2025) | B3: 2021 | C3: 2022 | D3: 2023 | E3: =D3+1 -> 2024 | F3: =E3+1 -> 2025 | G3: =F3+1 -> 2026 | H3: =G3+1 -> 2027 | I3: =H3+1 -> 2028 | J3: =I3+1 -> 2029 | K3: =J3+1 -> 2030
A4: Accounts Recievable | C4: =B.S!B5 -> 1016203 | D4: =B.S!C5 -> 1193964 | E4: =B.S!D5 -> 1221646 | F4: =B.S!E5 -> 1618072 | G4: =G5*I.S!G2/360 -> 1504459.7 | H4: =H5*I.S!H2/360 -> 1632338.7 | I4: =I5*I.S!I2/360 -> 1775984.5 | J4: =J5*I.S!J2/360 -> 1909183.4 | K4: =K5*I.S!K2/360 -> 2044735.4
A5: Accounts Recievable Collection Period | D5: =360/(I.S!D2/AVERAGE('Working Capital Schedule'!C4:D4)) -> 55.718285 | E5: =360/(I.S!E2/AVERAGE('Working Capital Schedule'!D4:E4)) -> 58.031054 | F5: =360/(I.S!F2/AVERAGE('Working Capital Schedule'!E4:F4)) -> 61.626248 | G5: =AVERAGE(D5:F5) -> 58.458529 | H5: 58.458529 | I5: 58.458529 | J5: 58.458529 | K5: 58.458529
A6: Inventory | C6: =B.S!B6 -> 935631 | D6: =B.S!C6 -> 971406 | E6: =B.S!D6 -> 737107 | F6: =B.S!E6 -> 799623 | G6: =G7*-I.S!G4/360 -> 907169.93 | H6: =H7*-I.S!H4/360 -> 984279.37 | I6: =I7*-I.S!I4/360 -> 1070896 | J6: =J7*-I.S!J4/360 -> 1151213.2 | K6: =K7*-I.S!K4/360 -> 1232949.3
A7: Inventory Processing Period | D7: =360/(-I.S!D4/AVERAGE('Working Capital Schedule'!C6:D6)) -> 102.59564 | E7: =360/(-I.S!E4/AVERAGE('Working Capital Schedule'!D6:E6)) -> 89.299487 | F7: =360/(-I.S!F4/AVERAGE('Working Capital Schedule'!E6:F6)) -> 75.532556 | G7: =F7 -> 75.532556 | H7: 75.532556 | I7: 75.532556 | J7: 75.532556 | K7: 75.532556
A8: Prepaid expenses and other assets | C8: =B.S!B7 -> 109823 | D8: =B.S!C7 -> 116195 | E8: =B.S!D7 -> 107262 | F8: =B.S!E7 -> 103551 | G8: =G9*-I.S!G15/360 -> 119942.84 | H8: =H9*-I.S!H15/360 -> 130137.99 | I8: =I9*-I.S!I15/360 -> 141590.13 | J8: =J9*-I.S!J15/360 -> 152209.39 | K8: =K9*-I.S!K15/360 -> 163016.26
A9: Prepaid Expenses and Other Assets Processing Period | D9: =360/(-I.S!D15/AVERAGE('Working Capital Schedule'!C8:D8)) -> 22.959548 | E9: =360/(-I.S!E15/AVERAGE('Working Capital Schedule'!D8:E8)) -> 19.734691 | F9: =360/(-I.S!F15/AVERAGE('Working Capital Schedule'!E8:F8)) -> 18.083464 | G9: =F9 -> 18.083464 | H9: 18.083464 | I9: 18.083464 | J9: 18.083464 | K9: 18.083464
A10: Prepaid income taxes | C10: =B.S!B8 -> 33785 | D10: =B.S!C8 -> 54151 | E10: =B.S!D8 -> 42202 | F10: =B.S!E8 -> 74637 | G10: =G11*-I.S!G29/360 -> 52585.934 | H10: =H11*-I.S!H29/360 -> 57706.619 | I10: =I11*-I.S!I29/360 -> 63438.905 | J10: =J11*-I.S!J29/360 -> 68856.642 | K10: =K11*-I.S!K29/360 -> 74420.173
A11: Prepaid Income Taxes Processing Period | D11: =360/(-I.S!D29/AVERAGE('Working Capital Schedule'!C10:D10)) -> 36.179879 | E11: =360/(-I.S!E29/AVERAGE('Working Capital Schedule'!D10:E10)) -> 36.101463 | F11: =360/(-I.S!F29/AVERAGE('Working Capital Schedule'!E10:F10)) -> 36.442782 | G11: =AVERAGE(D11:F11) -> 36.241375 | H11: 36.241375 | I11: 36.241375 | J11: 36.241375 | K11: 36.241375
A12: Current Assets | C12: =C10+C8+C6+C4 -> 2095442 | D12: =D10+D8+D6+D4 -> 2335716 | E12: =E10+E8+E6+E4 -> 2108217 | F12: =F10+F8+F6+F4 -> 2595883 | G12: =G10+G8+G6+G4 -> 2584158.4 | H12: =H10+H8+H6+H4 -> 2804462.7 | I12: =I10+I8+I6+I4 -> 3051909.5 | J12: =J10+J8+J6+J4 -> 3281462.6 | K12: =K10+K8+K6+K4 -> 3515121.1
A14: Accounts Payable | C14: =B.S!B24 -> 444265 | D14: =B.S!C24 -> 564379 | E14: =B.S!D24 -> 466775 | F14: =B.S!E24 -> 565974 | G14: =G15*-I.S!G4/360 -> 609657.41 | H14: =H15*-I.S!H4/360 -> 661478.29 | I14: =I15*-I.S!I4/360 -> 719688.38 | J14: =J15*-I.S!J4/360 -> 773665.01 | K14: =K15*-I.S!K4/360 -> 828595.23
A15: Accounts Payable - Payable Period | D15: =360/(-I.S!D4/AVERAGE('Working Capital Schedule'!C14:D14)) -> 54.263489 | E15: =360/(-I.S!E4/AVERAGE('Working Capital Schedule'!D14:E14)) -> 53.895711 | F15: =360/(-I.S!F4/AVERAGE('Working Capital Schedule'!E14:F14)) -> 50.761143 | G15: =F15 -> 50.761143 | H15: 50.761143 | I15: 50.761143 | J15: 50.761143 | K15: 50.761143
A16: Accrued Liabilities | C16: =B.S!B25 -> 172991 | D16: =B.S!C25 -> 183988 | E16: =B.S!D25 -> 220764 | F16: =B.S!E25 -> 306085 | G16: =G17*-I.S!$G$15/360 -> 259122.61 | H16: =H17*-I.S!$H$15/360 -> 281148.05 | I16: =I17*-I.S!$I$15/360 -> 305889.07 | J16: =J17*-I.S!$J$15/360 -> 328830.75 | K16: =K17*-I.S!$K$15/360 -> 352177.74
A17: Accrued Liabilities Days | D17: =360/(-I.S!$D$15/AVERAGE('Working Capital Schedule'!C16:D16)) -> 36.262937 | E17: =360/(-I.S!$E$15/AVERAGE('Working Capital Schedule'!D16:E16)) -> 35.745828 | F17: =360/(-I.S!$F$15/AVERAGE('Working Capital Schedule'!E16:F16)) -> 45.192918 | G17: =AVERAGE(D17:F17) -> 39.067228 | H17: 39.06723 | I17: 39.06723 | J17: 39.06723 | K17: 39.06723
A18: Accrued Promotion Alllowances | C18: =B.S!B26 -> 255631 | D18: =B.S!C26 -> 269061 | E18: =B.S!D26 -> 267711 | F18: =B.S!E26 -> 384070 | G18: =G19*-I.S!$G$15/360 -> 346260.8 | H18: =H19*-I.S!$H$15/360 -> 375692.98 | I18: =I19*-I.S!$I$15/360 -> 408753.97 | J18: =J19*-I.S!$J$15/360 -> 439410.52 | K18: =K19*-I.S!$K$15/360 -> 470608.66
A19: Accrued Promotion Alllowances Days | D19: =360/(-I.S!$D$15/AVERAGE('Working Capital Schedule'!C18:D18)) -> 53.299698 | E19: =360/(-I.S!$E$15/AVERAGE('Working Capital Schedule'!D18:E18)) -> 47.405225 | F19: =360/(-I.S!$F$15/AVERAGE('Working Capital Schedule'!E18:F18)) -> 55.909541 | G19: =AVERAGE(D19:F19) -> 52.204821 | H19: 52.204824 | I19: 52.204824 | J19: 52.204824 | K19: 52.204824
A20: Accrued Compensation | C20: =B.S!B27 -> 43311 | D20: =B.S!C27 -> 41914 | E20: =B.S!D27 -> 45809 | F20: =B.S!E27 -> 45323 | G20: =G21*-I.S!$G$15/360 -> 53552.616 | H20: =H21*-I.S!$H$15/360 -> 58104.592 | I20: =I21*-I.S!$I$15/360 -> 63217.796 | J20: =J21*-I.S!$J$15/360 -> 67959.13 | K20: =K21*-I.S!$K$15/360 -> 72784.229
A21: Accrued Compensation Days | D21: =360/(-I.S!$D$15/AVERAGE('Working Capital Schedule'!C20:D20)) -> 8.6573967 | E21: =360/(-I.S!$E$15/AVERAGE('Working Capital Schedule'!D20:E20)) -> 7.7472904 | F21: =360/(-I.S!$F$15/AVERAGE('Working Capital Schedule'!E20:F20)) -> 7.8172703 | G21: =AVERAGE(D21:F21) -> 8.0739858 | H21: 8.0739862 | I21: 8.0739862 | J21: 8.0739862 | K21: 8.0739862
A22: Income Tax Payable | C22: =B.S!B28 -> 72463 | D22: =B.S!C28 -> 87392 | E22: =B.S!D28 -> 92454 | F22: =B.S!E28 -> 114023 | G22: =G23*-I.S!G29/360 -> 95550.598 | H22: =H23*-I.S!H29/360 -> 104855.07 | I22: =I23*-I.S!I29/360 -> 115270.85 | J22: =J23*-I.S!J29/360 -> 125115.08 | K22: =K23*-I.S!K29/360 -> 135224.22
A23: Income Tax Payable Days | D23: =360/(-I.S!D29/AVERAGE('Working Capital Schedule'!C22:D22)) -> 65.769816 | E23: =360/(-I.S!E29/AVERAGE('Working Capital Schedule'!D22:E22)) -> 67.384552 | F23: =360/(-I.S!F29/AVERAGE('Working Capital Schedule'!E22:F22)) -> 64.401409 | G23: =AVERAGE(D23:F23) -> 65.851926 | H23: 65.851926 | I23: 65.851926 | J23: 65.851926 | K23: 65.851926
A24: Deferred Revenue | C24: =B.S!B29 -> 13317 | D24: =B.S!C29 -> 14955 | E24: =B.S!D29 -> 4006 | F24: =B.S!E29 -> 32305 | G24: =G25*I.S!G2/360 -> 16781.677 | H24: =H25*I.S!H2/360 -> 18208.119 | I24: =I25*I.S!I2/360 -> 19810.434 | J24: =J25*I.S!J2/360 -> 21296.216 | K24: =K25*I.S!K2/360 -> 22808.248
A25: Deferred Revenue Days | D25: =360/(I.S!D2/AVERAGE('Working Capital Schedule'!C24:D24)) -> 0.7127368 | E25: =360/(I.S!E2/AVERAGE('Working Capital Schedule'!D24:E24)) -> 0.45550681 | F25: =360/(I.S!F2/AVERAGE('Working Capital Schedule'!E24:F24)) -> 0.78800455 | G25: =AVERAGE(D25:F25) -> 0.65208272 | H25: 0.65208272 | I25: 0.65208272 | J25: 0.65208272 | K25: 0.65208272
A26: Current Liabilities | C26: =C24+C22+C20+C18+C16+C14 -> 1001978 | D26: =D24+D22+D20+D18+D16+D14 -> 1161689 | E26: =E24+E22+E20+E18+E16+E14 -> 1097519 | F26: =F24+F22+F20+F18+F16+F14 -> 1447780 | G26: =G24+G22+G20+G18+G16+G14 -> 1380925.7 | H26: =H24+H22+H20+H18+H16+H14 -> 1499487.1 | I26: =I24+I22+I20+I18+I16+I14 -> 1632630.5 | J26: =J24+J22+J20+J18+J16+J14 -> 1756276.7 | K26: =K24+K22+K20+K18+K16+K14 -> 1882198.3
A28: Total working capital | C28: =C12-C26 -> 1093464 | D28: =D12-D26 -> 1174027 | E28: =E12-E26 -> 1010698 | F28: =F12-F26 -> 1148103 | G28: =G12-G26 -> 1203232.7 | H28: =H12-H26 -> 1304975.6 | I28: =I12-I26 -> 1419279 | J28: =J12-J26 -> 1525185.9 | K28: =K12-K26 -> 1632922.8
A29: Change in working capital | G29: =(G28-F28)*-1 -> -55129.652 | H29: =(H28-G28)*-1 -> -101742.95 | I29: =(I28-H28)*-1 -> -114303.43 | J29: =(J28-I28)*-1 -> -105906.83 | K29: =(K28-J28)*-1 -> -107736.93
A31: Match (Y/N)

Sheet Depreciation Schedule
A1: Depreciation Schedule
D2: Historical | G2: Projections
A3: Period Ending September | D3: 2021 | E3: 2022 | F3: 2023 | G3: =F3+1 -> 2024 | H3: =G3+1 -> 2025 | I3: =H3+1 -> 2026 | J3: =I3+1 -> 2027 | K3: =J3+1 -> 2028 | L3: =K3+1 -> 2029 | M3: =L3+1 -> 2030
A4: PP&E in Jan | I4: =B.S!E13 -> 1081544
A5: Capital Expenditure | I5: =('C.S'!G34)*-1 -> 147751.17 | J5: =('C.S'!H34)*-1 -> 160310.02 | K5: =('C.S'!I34)*-1 -> 174417.31 | L5: =('C.S'!J34)*-1 -> 187498.61 | M5: =('C.S'!K34)*-1 -> 200811.01
A6: % Growth | J6: =J5/I5-1 -> 0.085 | K6: =K5/J5-1 -> 0.088 | L6: =L5/K5-1 -> 0.075 | M6: =M5/L5-1 -> 0.071
A8: Straight line Depreciation Years
A9: Years:
A10: Property, plant and equipment | I10: 9.5
A11: CAPEX | I11: 14 | J11: 14 | K11: 14 | L11: 14 | M11: 14
A12: Depreciation
A13: Existing PP &E | I13: =$I$4/$I$10 -> 113846.74 | J13: =$I$4/$I$10 -> 113846.74 | K13: =$I$4/$I$10 -> 113846.74 | L13: =$I$4/$I$10 -> 113846.74 | M13: =$I$4/$I$10 -> 113846.74
A14: 2026E CAPEX | I14: =$I$5/$I$11 -> 10553.655 | J14: =$I$5/$I$11 -> 10553.655 | K14: =$I$5/$I$11 -> 10553.655 | L14: =$I$5/$I$11 -> 10553.655 | M14: =$I$5/$I$11 -> 10553.655
A15: 2027E CAPEX | J15: =$J$5/$J$11 -> 11450.716 | K15: =$J$5/$J$11 -> 11450.716 | L15: =$J$5/$J$11 -> 11450.716 | M15: =$J$5/$J$11 -> 11450.716
A16: 2028E CAPEX | K16: =$K$5/$K$11 -> 12458.379 | L16: =$K$5/$K$11 -> 12458.379 | M16: =$K$5/$K$11 -> 12458.379
A17: 2029E CAPEX | L17: =$L$5/$L$11 -> 13392.758 | M17: =$L$5/$L$11 -> 13392.758
A18: 2030E CAPEX | M18: =$M$5/$M$11 -> 14343.643
A19: Total book depreciation | D19: ='C.S'!B4 -> 50155 | E19: ='C.S'!C4 -> 61241 | F19: ='C.S'!D4 -> 68898 | G19: ='C.S'!E4 -> 80434 | H19: ='C.S'!F4 -> 114441 | I19: =SUM(I13:I18) -> 124400.39 | J19: =SUM(J13:J18) -> 135851.11 | K19: =SUM(K13:K18) -> 148309.49 | L19: =SUM(L13:L18) -> 161702.24 | M19: =SUM(M13:M18) -> 176045.89
E20: =E19/D19-1 -> 0.22103479 | F20: =F19/E19-1 -> 0.12503062 | G20: =G19/F19-1 -> 0.16743592 | H20: =H19/G19-1 -> 0.42279384 | I20: =I19/H19-1 -> 0.087026435 | J20: =J19/I19-1 -> 0.092047267 | K20: =K19/J19-1 -> 0.091706128 | L20: =L19/K19-1 -> 0.09030277 | M20: =M19/L19-1 -> 0.088704046
A22: Accelerated Depreciation (%)
A23: Existing PP &E | I23: 0.1382 | J23: 0.1361 | K23: 0.1146 | L23: 0.0965 | M23: 0.0915
A24: 2026E CAPEX | I24: 0.0938 | J24: 0.0971 | K24: 0.0867 | L24: 0.0774 | M24: 0.0691
A25: 2027E CAPEX | J25: 0.0938 | K25: 0.0971 | L25: 0.0867 | M25: 0.0774
A26: 2028E CAPEX | K26: 0.0938 | L26: 0.0971 | M26: 0.0867
A27: 2029E CAPEX | L27: 0.0938 | M27: 0.0971
A28: 2030E CAPEX | M28: 0.0938
A30: Accelerated Depreciation (%)
A31: Existing PP &E | I31: =$I$4*I23 -> 149469.38 | J31: =$I$4*J23 -> 147198.14 | K31: =$I$4*K23 -> 123944.94 | L31: =$I$4*L23 -> 104369 | M31: =$I$4*M23 -> 98961.276
A32: 2026E CAPEX | I32: =$I$5*I24 -> 13859.06 | J32: =$I$5*J24 -> 14346.639 | K32: =$I$5*K24 -> 12810.027 | L32: =$I$5*L24 -> 11435.941 | M32: =$I$5*M24 -> 10209.606
A33: 2027E CAPEX | J33: =$J$5*J25 -> 15037.08 | K33: =$J$5*K25 -> 15566.103 | L33: =$J$5*L25 -> 13898.879 | M33: =$J$5*M25 -> 12407.996
A34: 2028E CAPEX | K34: =$K$5*K26 -> 16360.343 | L34: =$K$5*L26 -> 16935.921 | M34: =$K$5*M26 -> 15121.981
A35: 2029E CAPEX | L35: =$L$5*L27 -> 17587.369 | M35: =$L$5*M27 -> 18206.115
A36: 2030E CAPEX | M36: =$M$5*M28 -> 18836.072
A37: Total Tax Depreciation | I37: =SUM(I31:I36) -> 163328.44 | J37: =SUM(J31:J36) -> 176581.86 | K37: =SUM(K31:K36) -> 168681.42 | L37: =SUM(L31:L36) -> 164227.11 | M37: =SUM(M31:M36) -> 173743.05
A38: Difference in depreciation | I38: =I37-I19 -> 38928.049 | J38: =J37-J19 -> 40730.75 | K38: =K37-K19 -> 20371.929 | L38: =L37-L19 -> 2524.8609 | M38: =M37-M19 -> -2302.8426
A39: Tax rate % | I39: =I.S!G30 -> 0.21 | J39: =I.S!H30 -> 0.21 | K39: =I.S!I30 -> 0.21 | L39: =I.S!J30 -> 0.21 | M39: =I.S!K30 -> 0.21
A40: Deferred taxes | I40: =I38*I39 -> 8174.8903 | J40: =J38*J39 -> 8553.4574 | K40: =K38*K39 -> 4278.105 | L40: =L38*L39 -> 530.2208 | M40: =M38*M39 -> -483.59694

Sheet Debt Schedule
A1: Debt Schedule
B2: Actuals | E2: Projections
A3: DCF (30/09/2026) | B3: 2021 | C3: 2022 | D3: 2023 | E3: =D3+1 -> 2024 | F3: =E3+1 -> 2025 | G3: =F3+1 -> 2026 | H3: =G3+1 -> 2027 | I3: =H3+1 -> 2028 | J3: =I3+1 -> 2029 | K3: =J3+1 -> 2030
A5: Cash available to pay down debt
A6: Cash at beginning of year | G6: =F29 -> 2088117 | H6: =G29 -> 3765143.5 | I6: =H29 -> 5752104.1 | J6: =I29 -> 7747041.5 | K6: =J29 -> 10112562
A7: Cash flow before debt paydown | G7: ='C.S'!G60 -> 1677026.5 | H7: ='C.S'!H60 -> 1986960.6 | I7: ='C.S'!I60 -> 1994937.4 | J7: ='C.S'!J60 -> 2365521 | K7: ='C.S'!K60 -> 2380296.5
A8: Minimum cash cushion | G8: -1000000 | H8: -1000000 | I8: -1000000 | J8: -1000000 | K8: -1000000
A9: Total cash available to pay down debt | G9: =SUM(G6:G8) -> 2765143.5 | H9: =SUM(H6:H8) -> 4752104.1 | I9: =SUM(I6:I8) -> 6747041.5 | J9: =SUM(J6:J8) -> 9112562.4 | K9: =SUM(K6:K8) -> 11492859
A11: Payments on short-term debt
A12: Short term debt (beginning of year) | G12: =F15 -> 0 | H12: =G15 -> 0 | I12: =H15 -> 0 | J12: =I15 -> 0 | K12: =J15 -> 0
A13: Mandatory issuances/ (retirements) | G13: 0 | H13: 0 | I13: 0 | J13: 0 | K13: 0
A14: Non-mandatory issuances / (retirements)
A15: Short term debt (end of year) | F15: =B.S!E30 -> 0 | G15: =SUM(G12:G14) -> 0 | H15: =SUM(H12:H14) -> 0 | I15: =SUM(I12:I14) -> 0 | J15: =SUM(J12:J14) -> 0 | K15: =SUM(K12:K14) -> 0
A16: Short term interest expense | G16: =AVERAGE(F15:G15)*G17 -> 0 | H16: =AVERAGE(G15:H15)*H17 -> 0 | I16: =AVERAGE(H15:I15)*I17 -> 0 | J16: =AVERAGE(I15:J15)*J17 -> 0 | K16: =AVERAGE(J15:K15)*K17 -> 0
A17: Short term interest rate | G17: =6.6/(375*(4/12)) -> 0.0528 | H17: 0.0528 | I17: 0.0528 | J17: 0.0528 | K17: 0.0528
A19: Other long term debt
A20: Other long term debt (beginning of year) | G20: =F23 -> 0 | H20: =G23 -> 0 | I20: =H23 -> 0 | J20: =I23 -> 0 | K20: =J23 -> 0
A21: Mandatory issuances/ (retirements) | G21: 0 | H21: 0 | I21: 0 | J21: 0 | K21: 0
A22: Non-mandatory issuances / (retirements)
A23: Other long term debt (end of year) | F23: =B.S!E37 -> 0 | G23: =SUM(G20:G22) -> 0 | H23: =SUM(H20:H22) -> 0 | I23: =SUM(I20:I22) -> 0 | J23: =SUM(J20:J22) -> 0 | K23: =SUM(K20:K22) -> 0
A24: Other long term debt interest expense | G24: =AVERAGE(F23:G23)*G25 -> 0 | H24: =AVERAGE(G23:H23)*H25 -> 0 | I24: =AVERAGE(H23:I23)*I25 -> 0 | J24: =AVERAGE(I23:J23)*J25 -> 0 | K24: =AVERAGE(J23:K23)*K25 -> 0
A25: Other long term debt interest rate | G25: 0 | H25: 0 | I25: 0 | J25: 0 | K25: 0
A27: Total issuances/(retirements) | G27: =G13+G14+G21+G22 -> 0 | H27: =H13+H14+H21+H22 -> 0 | I27: =I13+I14+I21+I22 -> 0 | J27: =J13+J14+J21+J22 -> 0 | K27: =K13+K14+K21+K22 -> 0
A28: Total interest expense | G28: =G16+G24 -> 0 | H28: =H16+H24 -> 0 | I28: =I16+I24 -> 0 | J28: =J16+J24 -> 0 | K28: =K16+K24 -> 0
A29: Cash at the end of the year | F29: =B.S!E3 -> 2088117 | G29: =G27+G6+G7 -> 3765143.5 | H29: =H27+H6+H7 -> 5752104.1 | I29: =I27+I6+I7 -> 7747041.5 | J29: =J27+J6+J7 -> 10112562 | K29: =K27+K6+K7 -> 12492859
A30: Interest Income | G30: =AVERAGE(F29:G29)*G31 -> 58532.605 | H30: =AVERAGE(G29:H29)*H31 -> 95172.475 | I30: =AVERAGE(H29:I29)*I31 -> 134991.46 | J30: =AVERAGE(I29:J29)*J31 -> 178596.04 | K30: =AVERAGE(J29:K29)*K31 -> 226054.21
A31: Interest rate | G31: 0.02 | H31: 0.02 | I31: 0.02 | J31: 0.02 | K31: 0.02
A33: Match (Y/N)
